#VRML_SIM R2020a utf8
WorldInfo {
  info [
    "This demonstration shows a DJI Mavic 2 PRO flying over a rural area."
    "After the drone has taken off, you can control it with the keyboard of your computer."
  ]
  title "DJI Mavic 2 PRO demo"
  basicTimeStep 16
  defaultDamping Damping {
    linear 0.5
    angular 0.5
  }
}
Viewpoint {
  orientation -0.014918583187040903 -0.9990168282181889 -0.041747009624174714 3.513337803056105
  position -25.20226661246963 0.5348505284014977 -4.8340747238965305
  near 0.2
  follow "MiniNezha"
  followType "Mounted Shot"
  followSmoothness 0.2
}
TexturedBackground {
  luminosity 3
}
TexturedBackgroundLight {
}
Floor {
  size 400 400
  tileSize 6 6
  appearance SandyGround {
  }
}
Robot {
  translation 2.93606 0 6.05729
  rotation 0 1 0 -1.8325953071795862
  children [
    SliderJoint {
      jointParameters JointParameters {
        position 0.5200000000000004
      }
      device [
        PositionSensor {
        }
        LinearMotor {
        }
      ]
      endPoint Solid {
        translation 0 0 0.5200000000000004
        rotation 0 0 1 -1.5708003061004252
        children [
          Shape {
            geometry Cylinder {
              radius 0.05
            }
          }
        ]
      }
    }
    Shape {
      appearance PBRAppearance {
      }
    }
  ]
  controller "linear"
}
CrashBarrier {
  translation -15.2429 -1.18637e-05 2.52816
  rotation 3.0578999999772855e-06 0.9999999999925719 2.3464099999825706e-06 1.309
  name "crash barrier(1)"
  poleAppearance PBRAppearance {
    roughness 0.7
    IBLStrength 2
  }
  path [
    0 0 0
    2.1 0 0
  ]
  enableBoundingObject TRUE
}
Road {
  translation -43.8 0.01 -9.2
  rotation 0 1 0 1.1781
  width 1
  numberOfLanes 1
  rightBorder FALSE
  leftBorder FALSE
  wayPoints [
    0 0 0
    0 0 100
    200 0 200
  ]
  splineSubdivision 8
  appearance NULL
}
WoodenBox {
  translation -23.5212 0.2 -1.30482
  rotation -4.450439999940937e-06 0.9999999999867288 2.5953599999655566e-06 -1.8325953071795862
  name "wooden box(1)"
  size 0.3 0.3 0.3
}
Road {
  translation -43.8 0.012 -9.2
  rotation 0 1 0 1.1781
  name "road(1)"
  width 1.5
  numberOfLanes 1
  rightBorder FALSE
  leftBorder FALSE
  wayPoints [
    0 0 0
    0 0 100
    200 0 200
  ]
  splineSubdivision 8
}
CrashBarrier {
  translation -4.71204 -2.50961e-05 5.34955
  rotation 3.0578999999772855e-06 0.9999999999925719 2.3464099999825706e-06 1.309
  name "crash barrier(2)"
  poleAppearance PBRAppearance {
    roughness 0.7
    IBLStrength 2
  }
  path [
    0 0 0
    2.1 0 0
  ]
  enableBoundingObject TRUE
}
WoodenBox {
  translation -20.1322 0.2 -0.18
  rotation -0.9351132545462786 -0.25056306820553154 -0.25056206820525934 1.63783
  name "wooden box(2)"
  size 0.3 0.3 0.3
}
SmallManor {
  translation -50.35 0 -11.25
  rotation 0 1 0 4.32
}
TeslaModel3Simple {
  translation -41.5139 0.31 -4.34169
  rotation 0 -1 0 -1.309
  color 1 1 1
}
Pine {
  translation -14.0083 0 14.4828
  rotation 0 1 0 3.14159
}
Pine {
  translation -19.6195 0 24.3783
  rotation 0 1 0 2.87979
  name "pine tree(1)"
}
Pine {
  translation -10.6926 0 25.1339
  name "pine tree(4)"
}
Pine {
  translation -23.6341 0 -9.1421
  name "pine tree(5)"
}
Pine {
  translation -26.6328 0 7.1707
  name "pine tree(6)"
}
Pine {
  translation -14.6876 0 -10.9509
  rotation 0 1 0 -2.618
  name "pine tree(2)"
}
Forest {
  translation 0 -0.01 0
  shape [
    200 200
    200 0
    50 0
    50 50
    -50 50
    -50 -50
    50 -50
    50 0
    200 0
    200 -200
    -200 -200
    -200 200
  ]
  density 0.01
  type "cherry tree"
  randomSeed 1
  maxHeight 12
  minHeight 6
  maxRadius 6
  minRadius 3
}
Robot {
  translation -26.0042 0.471892 -2.16655
  rotation -0.0002319931378719415 0.9999986738299929 0.0016119917616012178 -0.26180674114510194
  children [
    GPS {
    }
    Gyro {
    }
    InertialUnit {
      name "inertial_unit"
    }
    DEF LEFT_LEG Transform {
      translation 0 0 -0.125
      children [
        HingeJoint {
          jointParameters HingeJointParameters {
            position -0.2148878642339067
            axis 0 0 1
          }
          device [
            PositionSensor {
              name "left_hip_encoder"
            }
            RotationalMotor {
              name "left_hip_motor"
              maxVelocity 23.5
              maxTorque 35
            }
          ]
          endPoint Solid {
            rotation 0 0 -0.9999999999999999 0.21488786423390582
            children [
              DEF Hip_Motor_Transform Transform {
                rotation 1 0 0 1.57
                children [
                  DEF Motor_Shape Shape {
                    appearance DEF Motor_Color PBRAppearance {
                      baseColor 0.9 0.9 0.9
                      metalness 0.2
                    }
                    geometry Cylinder {
                      height 0.03
                      radius 0.02
                    }
                  }
                ]
              }
              DEF Hip_link Transform {
                translation 0 -0.11 0
                children [
                  Shape {
                    appearance PBRAppearance {
                      baseColor 0.93 0.423 0
                      metalness 0.4
                      emissiveColor 0.53 0.023 0
                    }
                    geometry Box {
                      size 0.02 0.22 0.02
                    }
                  }
                ]
              }
              Transform {
                translation 0 -0.22 0
                children [
                  HingeJoint {
                    jointParameters HingeJointParameters {
                      position 0.42558125699392324
                      axis 0 0 1
                    }
                    device [
                      PositionSensor {
                        name "left_keen_encoder"
                      }
                      RotationalMotor {
                        name "left_keen_motor"
                        maxVelocity 23.5
                        maxTorque 35
                      }
                    ]
                    endPoint Solid {
                      rotation 0 0 1 0.4255812569939228
                      children [
                        Solid {
                          rotation 1 0 0 0
                          children [
                            USE Hip_Motor_Transform
                          ]
                          name "solid(1)"
                          boundingObject USE Hip_Motor_Transform
                          physics Physics {
                            density -1
                            mass 0.1
                          }
                        }
                        Transform {
                          translation 0 -0.22 0
                          rotation 1 0 0 -0.000795307179585869
                          children [
                            USE Hip_Motor_Transform
                          ]
                        }
                        USE Hip_link
                        Transform {
                          translation 0 -0.11 0
                          children [
                            HingeJoint {
                              jointParameters HingeJointParameters {
                                position -0.19947073479435543
                                axis 0 0 1
                                anchor 0 -0.11 0
                              }
                              device [
                                Brake {
                                  name "left_brake"
                                }
                                DEF left_wheel_encoder PositionSensor {
                                  name "left_wheel_encoder"
                                }
                                RotationalMotor {
                                  name "left_wheel_motor"
                                  maxVelocity 23.5
                                  maxTorque 35
                                }
                              ]
                              endPoint Solid {
                                translation 0 -0.11 -0.025000000000000015
                                rotation 0.9901267103486494 -0.0990793882525959 -0.0991583192558911 1.579922227034972
                                children [
                                  DEF wheel Shape {
                                    appearance PBRAppearance {
                                      baseColor 1 0 0
                                      roughness 0.5
                                      metalness 0.5
                                    }
                                    geometry DEF wheel Cylinder {
                                      height 0.03
                                      radius 0.05
                                    }
                                  }
                                ]
                                boundingObject USE wheel
                                physics Physics {
                                  density -1
                                  mass 1
                                }
                              }
                            }
                          ]
                        }
                      ]
                      boundingObject USE Hip_link
                      physics Physics {
                        density -1
                        mass 0.5
                        centerOfMass [
                          0 -0.22 0
                        ]
                      }
                    }
                  }
                ]
              }
            ]
            boundingObject USE Hip_link
            physics Physics {
              density -1
              mass 0.5
              centerOfMass [
                0 0 0
              ]
            }
          }
        }
      ]
    }
    DEF RIGHT_LEG Transform {
      translation 0 0 0.125
      children [
        HingeJoint {
          jointParameters HingeJointParameters {
            position -0.21488786497805723
            axis 0 0 1
          }
          device [
            PositionSensor {
              name "right_hip_encoder"
            }
            RotationalMotor {
              name "right_hip_motor"
              maxVelocity 23.5
              maxTorque 35
            }
          ]
          endPoint DEF hip_link Solid {
            rotation 0 0 -1 0.21488786497805748
            children [
              USE Hip_link
              USE Hip_Motor_Transform
              Transform {
                translation 0 -0.22 0
                children [
                  HingeJoint {
                    jointParameters HingeJointParameters {
                      position 0.4255812581364738
                      axis 0 0 1
                    }
                    device [
                      PositionSensor {
                        name "right_keen_encoder"
                      }
                      RotationalMotor {
                        name "right_keen_motor"
                        maxVelocity 23.5
                        maxTorque 35
                      }
                    ]
                    endPoint Solid {
                      rotation 0 0 1 0.42558125813647335
                      children [
                        Solid {
                          children [
                            USE Hip_Motor_Transform
                          ]
                          name "solid(1)"
                          boundingObject USE Hip_Motor_Transform
                          physics Physics {
                            density -1
                            mass 0.1
                          }
                        }
                        USE Hip_link
                        Transform {
                          translation 0 -0.22 0
                          rotation 1 0 0 -0.000795307179585869
                          children [
                            USE Hip_Motor_Transform
                          ]
                        }
                        Transform {
                          translation 0 -0.11 0
                          children [
                            HingeJoint {
                              jointParameters HingeJointParameters {
                                position -0.1993989048062466
                                axis 0 0 1
                                anchor 0 -0.11 0
                              }
                              device [
                                Brake {
                                  name "right_brake"
                                }
                                PositionSensor {
                                  name "right_wheel_encoder"
                                }
                                RotationalMotor {
                                  name "right_wheel_motor"
                                  maxVelocity 23.5
                                  maxTorque 35
                                }
                              ]
                              endPoint Solid {
                                translation 0 -0.11 0.024999999999999988
                                rotation 0.99013376163202 -0.09904417725109381 -0.09912308020375453 1.579915105759686
                                children [
                                  DEF wheel Shape {
                                    appearance PBRAppearance {
                                      baseColor 1 0 0
                                      roughness 0.5
                                      metalness 0.5
                                    }
                                    geometry DEF wheel Cylinder {
                                      height 0.03
                                      radius 0.05
                                    }
                                  }
                                ]
                                boundingObject USE wheel
                                physics Physics {
                                  density -1
                                  mass 1
                                }
                              }
                            }
                          ]
                        }
                      ]
                      boundingObject USE Hip_link
                      physics Physics {
                        density -1
                        mass 0.5
                        centerOfMass [
                          0 -0.22 0
                        ]
                      }
                    }
                  }
                ]
              }
              Shape {
              }
            ]
            name "solid(1)"
            boundingObject USE Hip_link
            physics Physics {
              density -1
              mass 0.5
              centerOfMass [
                0 0 0
              ]
            }
          }
        }
      ]
    }
    DEF BODY Shape {
      appearance Appearance {
        material Material {
          diffuseColor 0 0.247 0.263
          emissiveColor 0 0.047 0.063
        }
        texture ImageTexture {
          url [
            "textures/sustech1.png"
          ]
        }
        textureTransform TextureTransform {
        }
      }
      geometry Box {
        size 0.15 0.1 0.23
      }
    }
  ]
  name "MiniNezha"
  contactMaterial "body"
  boundingObject USE BODY
  physics Physics {
    density -1
    mass 5
    centerOfMass [
      0 0 0
    ]
  }
  controller "my_controller_python"
}
Solid {
  translation -11.1065 0 2.12198
  rotation 0 1 0 -0.261795307179586
  scale 1.5 1.5 1.5
  children [
    Solid {
      translation 0 -0.0013949928125521573 0
      children [
        DEF ramp Shape {
          appearance PBRAppearance {
            roughness 1
            metalness 0
            name "DefaultMaterial"
          }
          geometry IndexedFaceSet {
            coord Coordinate {
              point [
                1.97007 0.217516 0.7, 1.97007 0.217516 0, 2.78185 -2.71051e-17 0, 2.78185 -2.71051e-17 0.7, 0.15 0 0, 0 0 0.7, 0 0 0, 0 0 0.7, 0.965926 0.258819 0.7, 0 0 0, 0.965926 0.258819 0, 0.965926 0.258819 0, 0.15 0 0, 0 0 0, 0.96178 0.217516 0, 0.96178 0.217516 0, 0.15 0 0.7, 0.15 0 0, 1.96593 0.258819 -2.1684e-16, 2.93185 9.75782e-16 -2.1684e-16, 2.78185 -2.71051e-17 0, 1.97007 0.217516 0, 0.15 0 0.7, 0.15 0 0.7, 0.965926 0.258819 0.7, 0 0 0.7, 0.96178 0.217516 0.7, 0.96178 0.217516 0.7, 2.93185 9.75782e-16 0.7, 1.96593 0.258819 0.7, 2.78185 -2.71051e-17 0.7, 1.97007 0.217516 0.7, 1.96593 0.258819 -2.1684e-16, 2.93185 9.75782e-16 0.7, 2.93185 9.75782e-16 -2.1684e-16, 1.96593 0.258819 0.7, 2.93185 9.75782e-16 -2.1684e-16, 2.78185 -2.71051e-17 0.7, 2.78185 -2.71051e-17 0, 2.93185 9.75782e-16 0.7, 1.97007 0.217516 0, 0.96178 0.217516 0.7, 0.96178 0.217516 0, 1.97007 0.217516 0.7, 0.965926 0.258819 0.7, 1.96593 0.258819 0.7, 0.965926 0.258819 0, 1.96593 0.258819 -2.1684e-16
              ]
            }
            normal Normal {
              vector [
                -0.258819 -0.965926 0, -0.258819 -0.965926 0, -0.258819 -0.965926 0, -0.258819 -0.965926 0, 0 -1 0, 0 -1 0, 0 -1 0, -0.258819 0.965926 0, -0.258819 0.965926 0, -0.258819 0.965926 0, -0.258819 0.965926 0, 0 0 -1, 0 0 -1, 0 0 -1, 0 0 -1, 0.258819 -0.965926 0, 0.258819 -0.965926 0, 0.258819 -0.965926 0, -1.4456e-15 -5.39506e-15 -1, -1.4456e-15 -5.39506e-15 -1, -1.4456e-15 -5.39506e-15 -1, -1.4456e-15 -5.39506e-15 -1, 0 -1 0, 0 0 1, 0 0 1, 0 0 1, 0 0 1, 0.258819 -0.965926 0, 0 0 1, 0 0 1, 0 0 1, 0 0 1, 0.258819 0.965926 0, 0.258819 0.965926 0, 0.258819 0.965926 0, 0.258819 0.965926 0, 6.68591e-15 -1 0, 6.68591e-15 -1 0, 6.68591e-15 -1 0, 6.68591e-15 -1 0, 0 -1 0, 0 -1 0, 0 -1 0, 0 -1 0, 0 1 0, 0 1 0, 0 1 0, 0 1 0
              ]
            }
            coordIndex [
              0, 1, 2, -1, 3, 0, 2, -1, 4, 5, 6, -1, 7, 8, 9, -1, 8, 10, 9, -1, 11, 12, 13, -1, 11, 14, 12, -1, 15, 16, 17, -1, 18, 19, 20, -1, 21, 18, 20, -1, 4, 22, 5, -1, 23, 24, 25, -1, 26, 24, 23, -1, 15, 27, 16, -1, 28, 29, 30, -1, 29, 31, 30, -1, 32, 33, 34, -1, 32, 35, 33, -1, 36, 37, 38, -1, 36, 39, 37, -1, 11, 21, 14, -1, 40, 41, 42, -1, 11, 18, 21, -1, 43, 41, 40, -1, 29, 24, 26, -1, 31, 29, 26, -1, 44, 45, 46, -1, 45, 47, 46, -1
            ]
          }
        }
      ]
      name ""
      boundingObject USE ramp
      physics Physics {
      }
      linearVelocity 0 -2.0223125583004864e-05 0
    }
  ]
  name "<STL_BINARY>"
}
