#VRML_SIM R2020a utf8
WorldInfo {
  info [
    "This demonstration shows a DJI Mavic 2 PRO flying over a rural area."
    "After the drone has taken off, you can control it with the keyboard of your computer."
  ]
  title "DJI Mavic 2 PRO demo"
  basicTimeStep 16
  defaultDamping Damping {
    linear 0.5
    angular 0.5
  }
}
Viewpoint {
  orientation -0.08116420431368863 0.7184397522679993 0.6908376757960019 2.9094350535438918
  position -10.874258589688333 3.5430713398340665 2.3318965923455037
  near 0.2
  follow "MiniNezha"
  followType "Mounted Shot"
  followSmoothness 0.2
}
TexturedBackground {
  luminosity 3
}
TexturedBackgroundLight {
}
Floor {
  size 400 400
  tileSize 6 6
  appearance SandyGround {
  }
}
Robot {
  translation 2.93606 0 6.05729
  rotation 0 1 0 -1.8325953071795862
  children [
    SliderJoint {
      jointParameters JointParameters {
        position 0.3384000000000006
      }
      device [
        PositionSensor {
        }
        LinearMotor {
        }
      ]
      endPoint Solid {
        translation 0 0 0.3384000000000006
        rotation 0 0 1 -1.5708003061004252
        children [
          Shape {
            geometry Cylinder {
              radius 0.05
            }
          }
        ]
      }
    }
    Shape {
      appearance PBRAppearance {
      }
    }
  ]
  controller "linear"
}
CrashBarrier {
  translation -15.2429 -1.18637e-05 2.52816
  rotation 3.0578999999772855e-06 0.9999999999925719 2.3464099999825706e-06 1.309
  name "crash barrier(1)"
  poleAppearance PBRAppearance {
    roughness 0.7
    IBLStrength 2
  }
  path [
    0 0 0
    2.1 0 0
  ]
  enableBoundingObject TRUE
}
Road {
  translation -43.8 0.01 -9.2
  rotation 0 1 0 1.1781
  width 1
  numberOfLanes 1
  rightBorder FALSE
  leftBorder FALSE
  wayPoints [
    0 0 0
    0 0 100
    200 0 200
  ]
  splineSubdivision 8
  appearance NULL
}
WoodenBox {
  translation -23.5212 0.2 -1.30482
  rotation -4.450439999940937e-06 0.9999999999867288 2.5953599999655566e-06 -1.8325953071795862
  name "wooden box(1)"
  size 0.3 0.3 0.3
}
Road {
  translation -43.8 0.012 -9.2
  rotation 0 1 0 1.1781
  name "road(1)"
  width 1.5
  numberOfLanes 1
  rightBorder FALSE
  leftBorder FALSE
  wayPoints [
    0 0 0
    0 0 100
    200 0 200
  ]
  splineSubdivision 8
}
CrashBarrier {
  translation -4.71204 -2.50961e-05 5.34955
  rotation 3.0578999999772855e-06 0.9999999999925719 2.3464099999825706e-06 1.309
  name "crash barrier(2)"
  poleAppearance PBRAppearance {
    roughness 0.7
    IBLStrength 2
  }
  path [
    0 0 0
    2.1 0 0
  ]
  enableBoundingObject TRUE
}
WoodenBox {
  translation -20.1322 0.2 -0.18
  rotation -0.9351132545462786 -0.25056306820553154 -0.25056206820525934 1.63783
  name "wooden box(2)"
  size 0.3 0.3 0.3
}
SmallManor {
  translation -50.35 0 -11.25
  rotation 0 1 0 4.32
}
TeslaModel3Simple {
  translation -41.5139 0.31 -4.34169
  rotation 0 -1 0 -1.309
  color 1 1 1
}
Pine {
  translation -14.0083 0 14.4828
  rotation 0 1 0 3.14159
}
Pine {
  translation -19.6195 0 24.3783
  rotation 0 1 0 2.87979
  name "pine tree(1)"
}
Pine {
  translation -10.6926 0 25.1339
  name "pine tree(4)"
}
Pine {
  translation -23.6341 0 -9.1421
  name "pine tree(5)"
}
Pine {
  translation -26.6328 0 7.1707
  name "pine tree(6)"
}
Pine {
  translation -14.6876 0 -10.9509
  rotation 0 1 0 -2.618
  name "pine tree(2)"
}
Forest {
  translation 0 -0.01 0
  shape [
    200 200
    200 0
    50 0
    50 50
    -50 50
    -50 -50
    50 -50
    50 0
    200 0
    200 -200
    -200 -200
    -200 200
  ]
  density 0.01
  type "cherry tree"
  randomSeed 1
  maxHeight 12
  minHeight 6
  maxRadius 6
  minRadius 3
}
Robot {
  translation -11.724377837730984 0.47812274519649567 2.40026669164343
  rotation -0.0003187059184571443 0.9999969382460745 0.002453961086537609 -0.2610643567413913
  children [
    GPS {
    }
    Gyro {
    }
    InertialUnit {
      name "inertial_unit"
    }
    DEF LEFT_LEG Transform {
      translation 0 0 -0.125
      children [
        HingeJoint {
          jointParameters HingeJointParameters {
            position -0.21570227875879888
            axis 0 0 1
          }
          device [
            PositionSensor {
              name "left_hip_encoder"
            }
            RotationalMotor {
              name "left_hip_motor"
              maxVelocity 23.5
              maxTorque 35
            }
          ]
          endPoint Solid {
            rotation 0 0 -1 0.21570227875879797
            children [
              DEF Hip_Motor_Transform Transform {
                rotation 1 0 0 1.57
                children [
                  DEF Motor_Shape Shape {
                    appearance DEF Motor_Color PBRAppearance {
                      baseColor 0.9 0.9 0.9
                      metalness 0.2
                    }
                    geometry Cylinder {
                      height 0.03
                      radius 0.02
                    }
                  }
                ]
              }
              DEF Hip_link Transform {
                translation 0 -0.11 0
                children [
                  Shape {
                    appearance PBRAppearance {
                      baseColor 0.93 0.423 0
                      metalness 0.4
                      emissiveColor 0.53 0.023 0
                    }
                    geometry Box {
                      size 0.02 0.22 0.02
                    }
                  }
                ]
              }
              Transform {
                translation 0 -0.22 0
                children [
                  HingeJoint {
                    jointParameters HingeJointParameters {
                      position 0.42719514719923823
                      axis 0 0 1
                    }
                    device [
                      PositionSensor {
                        name "left_keen_encoder"
                      }
                      RotationalMotor {
                        name "left_keen_motor"
                        maxVelocity 23.5
                        maxTorque 35
                      }
                    ]
                    endPoint Solid {
                      rotation 0 0 1 0.42719514719923796
                      children [
                        Solid {
                          rotation 1 0 0 0
                          children [
                            USE Hip_Motor_Transform
                          ]
                          name "solid(1)"
                          boundingObject USE Hip_Motor_Transform
                          physics Physics {
                            density -1
                            mass 0.1
                          }
                        }
                        Transform {
                          translation 0 -0.22 0
                          rotation 1 0 0 -0.000795307179585869
                          children [
                            USE Hip_Motor_Transform
                          ]
                        }
                        USE Hip_link
                        Transform {
                          translation 0 -0.11 0
                          children [
                            HingeJoint {
                              jointParameters HingeJointParameters {
                                position 0.9595498985709943
                                axis 0 0 1
                                anchor 0 -0.11 0
                              }
                              device [
                                Brake {
                                  name "left_brake"
                                }
                                DEF left_wheel_encoder PositionSensor {
                                  name "left_wheel_encoder"
                                }
                                RotationalMotor {
                                  name "left_wheel_motor"
                                  maxVelocity 23.5
                                  maxTorque 35
                                }
                              ]
                              endPoint Solid {
                                translation 0 -0.11 -0.024999999999999974
                                rotation 0.8053243942384155 0.4190302787004958 0.4193640966710357 1.784856362833854
                                children [
                                  DEF wheel Shape {
                                    appearance PBRAppearance {
                                      baseColor 1 0 0
                                      roughness 0.5
                                      metalness 0.5
                                    }
                                    geometry DEF wheel Cylinder {
                                      height 0.03
                                      radius 0.05
                                    }
                                  }
                                ]
                                boundingObject USE wheel
                                physics Physics {
                                  density -1
                                  mass 1
                                }
                                linearVelocity -0.00010369717192252253 8.897140590455285e-08 -2.7735379913146753e-05
                                angularVelocity -0.0005553338947774594 2.7472626695485503e-07 0.0020763384279376593
                              }
                            }
                          ]
                        }
                      ]
                      boundingObject USE Hip_link
                      physics Physics {
                        density -1
                        mass 0.5
                        centerOfMass [
                          0 -0.22 0
                        ]
                      }
                      linearVelocity -0.00010397741938702077 4.093433237929803e-08 -2.7829276489096613e-05
                      angularVelocity -2.7570070878036827e-06 2.7764526588638825e-07 8.00695875840507e-06
                    }
                  }
                ]
              }
            ]
            boundingObject USE Hip_link
            physics Physics {
              density -1
              mass 0.5
              centerOfMass [
                0 0 0
              ]
            }
            linearVelocity -0.0001063362178186102 -6.321337256939946e-08 -2.8704675012531722e-05
            angularVelocity -1.76883167396013e-06 2.778204951018155e-07 4.307419781312199e-06
          }
        }
      ]
    }
    DEF RIGHT_LEG Transform {
      translation 0 0 0.125
      children [
        HingeJoint {
          jointParameters HingeJointParameters {
            position -0.21570221527125047
            axis 0 0 1
          }
          device [
            PositionSensor {
              name "right_hip_encoder"
            }
            RotationalMotor {
              name "right_hip_motor"
              maxVelocity 23.5
              maxTorque 35
            }
          ]
          endPoint DEF hip_link Solid {
            rotation 0 0 -1 0.2157022152712505
            children [
              USE Hip_link
              USE Hip_Motor_Transform
              Transform {
                translation 0 -0.22 0
                children [
                  HingeJoint {
                    jointParameters HingeJointParameters {
                      position 0.427194546582017
                      axis 0 0 1
                    }
                    device [
                      PositionSensor {
                        name "right_keen_encoder"
                      }
                      RotationalMotor {
                        name "right_keen_motor"
                        maxVelocity 23.5
                        maxTorque 35
                      }
                    ]
                    endPoint Solid {
                      rotation 0 0 1 0.4271945465820172
                      children [
                        Solid {
                          children [
                            USE Hip_Motor_Transform
                          ]
                          name "solid(1)"
                          boundingObject USE Hip_Motor_Transform
                          physics Physics {
                            density -1
                            mass 0.1
                          }
                        }
                        USE Hip_link
                        Transform {
                          translation 0 -0.22 0
                          rotation 1 0 0 -0.000795307179585869
                          children [
                            USE Hip_Motor_Transform
                          ]
                        }
                        Transform {
                          translation 0 -0.11 0
                          children [
                            HingeJoint {
                              jointParameters HingeJointParameters {
                                position 2.1506213118510367
                                axis 0 0 1
                                anchor 0 -0.11 0
                              }
                              device [
                                Brake {
                                  name "right_brake"
                                }
                                PositionSensor {
                                  name "right_wheel_encoder"
                                }
                                RotationalMotor {
                                  name "right_wheel_motor"
                                  maxVelocity 23.5
                                  maxTorque 35
                                }
                              ]
                              endPoint Solid {
                                translation 0 -0.11 0.02499999999999994
                                rotation 0.35685581764597313 0.6602874403554068 0.6608134544038347 2.455549654908045
                                children [
                                  DEF wheel Shape {
                                    appearance PBRAppearance {
                                      baseColor 1 0 0
                                      roughness 0.5
                                      metalness 0.5
                                    }
                                    geometry DEF wheel Cylinder {
                                      height 0.03
                                      radius 0.05
                                    }
                                  }
                                ]
                                boundingObject USE wheel
                                physics Physics {
                                  density -1
                                  mass 1
                                }
                                linearVelocity -0.00010556669457990276 -9.50931722341066e-08 -2.8232907353469025e-05
                                angularVelocity -0.0005653180164234431 2.84077264456705e-07 0.0021137078187258695
                              }
                            }
                          ]
                        }
                      ]
                      boundingObject USE Hip_link
                      physics Physics {
                        density -1
                        mass 0.5
                        centerOfMass [
                          0 -0.22 0
                        ]
                      }
                      linearVelocity -0.0001055582759956812 -1.094047249727631e-07 -2.8250291849115928e-05
                      angularVelocity -4.877880961463327e-07 2.7767800246379304e-07 -4.885544031540884e-07
                    }
                  }
                ]
              }
              Shape {
              }
            ]
            name "solid(1)"
            boundingObject USE Hip_link
            physics Physics {
              density -1
              mass 0.5
              centerOfMass [
                0 0 0
              ]
            }
            linearVelocity -0.00010626603880711189 9.006878824882786e-08 -2.8685333639339982e-05
            angularVelocity -1.6061362470352548e-06 2.778532693620432e-07 3.6973630567648286e-06
          }
        }
      ]
    }
    DEF BODY Shape {
      appearance Appearance {
        material Material {
          diffuseColor 0 0.247 0.263
          emissiveColor 0 0.047 0.063
        }
        texture ImageTexture {
          url [
            "sustech1.png"
          ]
        }
        textureTransform TextureTransform {
        }
      }
      geometry Box {
        size 0.15 0.1 0.23
      }
    }
  ]
  name "MiniNezha"
  contactMaterial "body"
  boundingObject USE BODY
  physics Physics {
    density -1
    mass 5
    centerOfMass [
      0 0 0
    ]
  }
  controller "my_controller_python"
  linearVelocity -0.00010630112312625157 1.3346349522428706e-08 -2.8694497800855014e-05
  angularVelocity -1.6539413766828245e-06 2.780372623674473e-07 3.875913677285239e-06
}
Solid {
  translation -11.1065 0 2.12198
  rotation 0 1 0 -0.261795307179586
  scale 1.5 1.5 1.5
  children [
    Solid {
      translation 1.578983857244667e-15 -0.004186632360501744 0
      rotation -0.0009768802523520681 0.9999994956542632 -0.00023322991186053226 1.110223584561688e-16
      children [
        DEF ramp Shape {
          appearance PBRAppearance {
            roughness 1
            metalness 0
            name "DefaultMaterial"
          }
          geometry IndexedFaceSet {
            coord Coordinate {
              point [
                1.97007 0.217516 0.7, 1.97007 0.217516 0, 2.78185 -2.71051e-17 0, 2.78185 -2.71051e-17 0.7, 0.15 0 0, 0 0 0.7, 0 0 0, 0 0 0.7, 0.965926 0.258819 0.7, 0 0 0, 0.965926 0.258819 0, 0.965926 0.258819 0, 0.15 0 0, 0 0 0, 0.96178 0.217516 0, 0.96178 0.217516 0, 0.15 0 0.7, 0.15 0 0, 1.96593 0.258819 -2.1684e-16, 2.93185 9.75782e-16 -2.1684e-16, 2.78185 -2.71051e-17 0, 1.97007 0.217516 0, 0.15 0 0.7, 0.15 0 0.7, 0.965926 0.258819 0.7, 0 0 0.7, 0.96178 0.217516 0.7, 0.96178 0.217516 0.7, 2.93185 9.75782e-16 0.7, 1.96593 0.258819 0.7, 2.78185 -2.71051e-17 0.7, 1.97007 0.217516 0.7, 1.96593 0.258819 -2.1684e-16, 2.93185 9.75782e-16 0.7, 2.93185 9.75782e-16 -2.1684e-16, 1.96593 0.258819 0.7, 2.93185 9.75782e-16 -2.1684e-16, 2.78185 -2.71051e-17 0.7, 2.78185 -2.71051e-17 0, 2.93185 9.75782e-16 0.7, 1.97007 0.217516 0, 0.96178 0.217516 0.7, 0.96178 0.217516 0, 1.97007 0.217516 0.7, 0.965926 0.258819 0.7, 1.96593 0.258819 0.7, 0.965926 0.258819 0, 1.96593 0.258819 -2.1684e-16
              ]
            }
            normal Normal {
              vector [
                -0.258819 -0.965926 0, -0.258819 -0.965926 0, -0.258819 -0.965926 0, -0.258819 -0.965926 0, 0 -1 0, 0 -1 0, 0 -1 0, -0.258819 0.965926 0, -0.258819 0.965926 0, -0.258819 0.965926 0, -0.258819 0.965926 0, 0 0 -1, 0 0 -1, 0 0 -1, 0 0 -1, 0.258819 -0.965926 0, 0.258819 -0.965926 0, 0.258819 -0.965926 0, -1.4456e-15 -5.39506e-15 -1, -1.4456e-15 -5.39506e-15 -1, -1.4456e-15 -5.39506e-15 -1, -1.4456e-15 -5.39506e-15 -1, 0 -1 0, 0 0 1, 0 0 1, 0 0 1, 0 0 1, 0.258819 -0.965926 0, 0 0 1, 0 0 1, 0 0 1, 0 0 1, 0.258819 0.965926 0, 0.258819 0.965926 0, 0.258819 0.965926 0, 0.258819 0.965926 0, 6.68591e-15 -1 0, 6.68591e-15 -1 0, 6.68591e-15 -1 0, 6.68591e-15 -1 0, 0 -1 0, 0 -1 0, 0 -1 0, 0 -1 0, 0 1 0, 0 1 0, 0 1 0, 0 1 0
              ]
            }
            coordIndex [
              0, 1, 2, -1, 3, 0, 2, -1, 4, 5, 6, -1, 7, 8, 9, -1, 8, 10, 9, -1, 11, 12, 13, -1, 11, 14, 12, -1, 15, 16, 17, -1, 18, 19, 20, -1, 21, 18, 20, -1, 4, 22, 5, -1, 23, 24, 25, -1, 26, 24, 23, -1, 15, 27, 16, -1, 28, 29, 30, -1, 29, 31, 30, -1, 32, 33, 34, -1, 32, 35, 33, -1, 36, 37, 38, -1, 36, 39, 37, -1, 11, 21, 14, -1, 40, 41, 42, -1, 11, 18, 21, -1, 43, 41, 40, -1, 29, 24, 26, -1, 31, 29, 26, -1, 44, 45, 46, -1, 45, 47, 46, -1
            ]
          }
        }
      ]
      name ""
      boundingObject USE ramp
      physics Physics {
      }
      linearVelocity -4.383851237715173e-14 6.78879789886543e-16 -1.0959628094287933e-14
      angularVelocity 2.010624564331145e-22 -1.3559026324073853e-15 9.683491443776263e-23
    }
  ]
  name "<STL_BINARY>"
}
