#VRML_SIM R2020a utf8
WorldInfo {
  basicTimeStep 16
}
Viewpoint {
  orientation 0.9349824679067317 -0.3401357884858429 -0.10057549452103723 5.670582404982246
  position 0.8131035840983831 1.2399144238579027 1.4844090331093056
  follow "MiniNezha"
  followSmoothness 0
}
TexturedBackground {
}
TexturedBackgroundLight {
}
Floor {
}
Robot {
  translation 0.22099193046261914 0.378497123315006 1.257585554002197e-05
  rotation 0.001468521166076108 0.08580017409420969 0.996311283470677 0.008428196807150342
  children [
    GPS {
    }
    Gyro {
    }
    InertialUnit {
      name "inertial_unit"
    }
    DEF LEFT_LEG Transform {
      translation 0 0 -0.125
      children [
        HingeJoint {
          jointParameters HingeJointParameters {
            position -0.731254065594114
            axis 0 0 1
          }
          device [
            PositionSensor {
              name "left_hip_encoder"
            }
            RotationalMotor {
              name "left_hip_motor"
            }
          ]
          endPoint DEF hip_link Solid {
            rotation 0 0 -1 0.7312540655941138
            children [
              DEF Hip_motor_shape Transform {
                rotation 1 0 0 1.57
                children [
                  Shape {
                    geometry Cylinder {
                      height 0.02
                      radius 0.02
                    }
                  }
                ]
              }
              DEF Hip_link Transform {
                translation 0 -0.11 0
                children [
                  Shape {
                    appearance PBRAppearance {
                      baseColor 0 0 0
                      roughness 0.5
                      metalness 0.5
                    }
                    geometry Box {
                      size 0.02 0.22 0.02
                    }
                  }
                ]
              }
              Transform {
                translation 0 -0.22 0
                children [
                  HingeJoint {
                    jointParameters HingeJointParameters {
                      position 1.4453890919470975
                      axis 0 0 1
                    }
                    device [
                      PositionSensor {
                        name "left_keen_encoder"
                      }
                      RotationalMotor {
                        name "left_keen_motor"
                      }
                    ]
                    endPoint Solid {
                      rotation 0 0 1 1.4453890919470977
                      children [
                        DEF Keen_motor_shape Transform {
                          translation 0 -0.22 0
                          rotation 1 0 0 1.57
                          children [
                            Shape {
                              geometry Cylinder {
                                height 0.02
                                radius 0.02
                              }
                            }
                          ]
                        }
                        DEF Keen_link Transform {
                          translation 0 -0.11 0
                          children [
                            Shape {
                              appearance PBRAppearance {
                                baseColor 0 0 0
                                roughness 0.5
                                metalness 0.5
                              }
                              geometry Box {
                                size 0.02 0.22 0.02
                              }
                            }
                          ]
                        }
                        Transform {
                          translation 0 -0.11 0
                          children [
                            HingeJoint {
                              jointParameters HingeJointParameters {
                                position 0.2604058056409379
                                axis 0 0 1
                                anchor 0 -0.11 0
                              }
                              device [
                                DEF left_wheel_encoder PositionSensor {
                                  name "left_wheel_encoder"
                                }
                                RotationalMotor {
                                  name "left_wheel_motor"
                                }
                              ]
                              endPoint Solid {
                                translation 0 -0.11 0
                                rotation 0.9832695136814049 0.12875294268016893 0.12885551294349173 1.5868713293225538
                                children [
                                  DEF wheel Shape {
                                    appearance PBRAppearance {
                                      baseColor 1 0 0
                                      roughness 0.5
                                      metalness 0.5
                                    }
                                    geometry DEF wheel Cylinder {
                                      height 0.01
                                      radius 0.05
                                    }
                                  }
                                ]
                                boundingObject USE wheel
                                physics Physics {
                                  density -1
                                  mass 1
                                }
                                linearVelocity 2.3169989270215253e-05 -1.2686891161692528e-10 -1.681171371821965e-08
                                angularVelocity -3.362339487784223e-07 -1.500115147353078e-07 -0.0004637534724957167
                              }
                            }
                          ]
                        }
                      ]
                      boundingObject USE Keen_motor_shape
                      physics Physics {
                        density -1
                        mass 0.1
                        centerOfMass [
                          0 -0.22 0
                        ]
                      }
                      linearVelocity 2.3170116301653722e-05 -1.292747597858579e-10 -1.6811717183651266e-08
                      angularVelocity 4.117347355519136e-09 -1.5440701696062705e-07 6.873527317928634e-06
                    }
                  }
                ]
              }
              Shape {
              }
            ]
            boundingObject USE Hip_motor_shape
            physics Physics {
              density -1
              mass 0.1
              centerOfMass [
                0 0 0
              ]
            }
            linearVelocity 2.090189381866246e-05 2.376193819486616e-10 -1.5444724976664512e-08
            angularVelocity 4.117329207823966e-09 -1.5440695277650319e-07 6.873530954315727e-06
          }
        }
      ]
    }
    DEF RIGHT_LEG Transform {
      translation 0 0 0.125
      children [
        HingeJoint {
          jointParameters HingeJointParameters {
            position -0.7312540654445563
            axis 0 0 1
          }
          device [
            PositionSensor {
              name "right_hip_encoder"
            }
            RotationalMotor {
              name "right_hip_motor"
            }
          ]
          endPoint DEF hip_link Solid {
            translation 6.100903188086059e-06 2.6040143698532543e-06 2.5998827495876675e-06
            rotation -1.185157321657213e-06 1.1224887525070188e-06 -0.9999999999986677 0.7312540654471849
            children [
              USE Hip_motor_shape
              DEF Hip_link Transform {
                translation 0 -0.11 0
                children [
                  Shape {
                    appearance PBRAppearance {
                      baseColor 0 0 0
                      roughness 0.5
                      metalness 0.5
                    }
                    geometry Box {
                      size 0.02 0.22 0.02
                    }
                  }
                ]
              }
              Transform {
                translation 0 -0.22 0
                children [
                  HingeJoint {
                    jointParameters HingeJointParameters {
                      position 1.4453890908495541
                      axis 0 0 1
                    }
                    device [
                      PositionSensor {
                        name "right_keen_encoder"
                      }
                      RotationalMotor {
                        name "right_keen_motor"
                      }
                    ]
                    endPoint Solid {
                      rotation 0 0 0.9999999999999999 1.445389090849554
                      children [
                        USE Keen_motor_shape
                        DEF Keen_link Transform {
                          translation 0 -0.11 0
                          children [
                            Shape {
                              appearance PBRAppearance {
                                baseColor 0 0 0
                                roughness 0.5
                                metalness 0.5
                              }
                              geometry Box {
                                size 0.02 0.22 0.02
                              }
                            }
                          ]
                        }
                        Transform {
                          translation 0 -0.11 0
                          children [
                            HingeJoint {
                              jointParameters HingeJointParameters {
                                position 0.2567242255307283
                                axis 0 0 1
                                anchor 0 -0.11 0
                              }
                              device [
                                PositionSensor {
                                  name "right_wheel_encoder"
                                }
                                RotationalMotor {
                                  name "right_wheel_motor"
                                }
                              ]
                              endPoint Solid {
                                translation 0 -0.11 0
                                rotation 0.9837329107950755 0.12697216841871756 0.12707332003885363 1.5864002175608178
                                children [
                                  DEF wheel Shape {
                                    appearance PBRAppearance {
                                      baseColor 1 0 0
                                      roughness 0.5
                                      metalness 0.5
                                    }
                                    geometry DEF wheel Cylinder {
                                      height 0.01
                                      radius 0.05
                                    }
                                  }
                                ]
                                boundingObject USE wheel
                                physics Physics {
                                  density -1
                                  mass 1
                                }
                                linearVelocity 2.3131385285570256e-05 1.1390503188259876e-10 -1.6782276482169127e-08
                                angularVelocity -3.36168255293297e-07 -1.5025994686029744e-07 -0.00046298139504722703
                              }
                            }
                          ]
                        }
                      ]
                      boundingObject USE Keen_motor_shape
                      physics Physics {
                        density -1
                        mass 0.1
                        centerOfMass [
                          0 -0.22 0
                        ]
                      }
                      linearVelocity 2.313151231520122e-05 1.1631609453388592e-10 -1.6782462958497834e-08
                      angularVelocity 4.116798714030516e-09 -1.544072447264213e-07 6.873526757186825e-06
                    }
                  }
                ]
              }
              Shape {
              }
            ]
            name "solid(1)"
            boundingObject USE Hip_motor_shape
            physics Physics {
              density -1
              mass 0.1
              centerOfMass [
                0 0 0
              ]
            }
            linearVelocity 2.0863289458355265e-05 4.879077764030627e-10 -1.541568520716484e-08
            angularVelocity 4.1173604357216166e-09 -1.544071432562494e-07 6.87353224133133e-06
          }
        }
      ]
    }
    DEF BODY Shape {
      appearance PBRAppearance {
        baseColor 0.3 0.3 0.3
        roughness 0.5
        metalness 0.5
      }
      geometry Box {
        size 0.15 0.1 0.23
      }
    }
  ]
  name "MiniNezha"
  boundingObject USE BODY
  physics Physics {
    density -1
    mass 5
    centerOfMass [
      0 0 0
    ]
  }
  controller "my_controller_python"
  linearVelocity 2.0882718114508587e-05 3.418735332161305e-10 -1.5430767320176366e-08
  angularVelocity 4.117568756588768e-09 -1.544070069040418e-07 6.873531262896924e-06
}
