#VRML_SIM R2020a utf8
WorldInfo {
  basicTimeStep 8
  contactProperties [
    ContactProperties {
      bounce 0
    }
    ContactProperties {
      material1 "body"
      coulombFriction [
        0
      ]
      bounce 0
    }
  ]
}
Viewpoint {
  orientation 0.04355756117688419 -0.9884624253813529 -0.14506816492096078 3.8844021566578095
  position 2.1545565223989476 1.1330163259683812 -2.138156299745215
  follow "MiniNezha"
  followSmoothness 0
}
TexturedBackground {
}
TexturedBackgroundLight {
}
Floor {
}
Robot {
  translation 0.27 0.49 0
  rotation 0 0 1 0
  children [
    GPS {
    }
    Gyro {
    }
    InertialUnit {
      name "inertial_unit"
    }
    DEF LEFT_LEG Transform {
      translation 0 0 -0.125
      children [
        HingeJoint {
          jointParameters HingeJointParameters {
            axis 0 0 1
          }
          device [
            PositionSensor {
              name "left_hip_encoder"
            }
            RotationalMotor {
              name "left_hip_motor"
              maxVelocity 23.5
              maxTorque 35
            }
          ]
          endPoint Solid {
            rotation 0 0 1 0
            children [
              DEF Hip_Motor_Transform Transform {
                rotation 1 0 0 1.57
                children [
                  DEF Motor_Shape Shape {
                    appearance DEF Motor_Color PBRAppearance {
                      baseColor 0.9 0.9 0.9
                      metalness 0.2
                    }
                    geometry Cylinder {
                      height 0.03
                      radius 0.02
                    }
                  }
                ]
              }
              DEF Hip_link Transform {
                translation 0 -0.11 0
                children [
                  Shape {
                    appearance PBRAppearance {
                      baseColor 0 0.247 0.263
                      roughness 0.5
                      metalness 0.5
                      emissiveColor 0 0.047 0.063
                    }
                    geometry Box {
                      size 0.02 0.22 0.02
                    }
                  }
                ]
              }
              Transform {
                translation 0 -0.22 0
                children [
                  HingeJoint {
                    jointParameters HingeJointParameters {
                      axis 0 0 1
                    }
                    device [
                      PositionSensor {
                        name "left_keen_encoder"
                      }
                      RotationalMotor {
                        name "left_keen_motor"
                        maxVelocity 23.5
                        maxTorque 35
                      }
                    ]
                    endPoint Solid {
                      rotation 0 0 1 0
                      children [
                        Solid {
                          rotation 1 0 0 0
                          children [
                            USE Hip_Motor_Transform
                          ]
                          name "solid(1)"
                          boundingObject USE Hip_Motor_Transform
                          physics Physics {
                            density -1
                            mass 0.1
                          }
                        }
                        Transform {
                          translation 0 -0.22 0
                          rotation 1 0 0 -0.000795307179585869
                          children [
                            USE Hip_Motor_Transform
                          ]
                        }
                        USE Hip_link
                        Transform {
                          translation 0 -0.11 0
                          children [
                            HingeJoint {
                              jointParameters HingeJointParameters {
                                axis 0 0 1
                                anchor 0 -0.11 0
                              }
                              device [
                                Brake {
                                  name "left_brake"
                                }
                                DEF left_wheel_encoder PositionSensor {
                                  name "left_wheel_encoder"
                                }
                                RotationalMotor {
                                  name "left_wheel_motor"
                                  maxVelocity 23.5
                                  maxTorque 35
                                }
                              ]
                              endPoint Solid {
                                translation 0 -0.11 -0.025000000000000015
                                rotation 1 7.853589927914979e-17 -7.853589927914979e-17 1.57
                                children [
                                  DEF Wheel Shape {
                                    appearance DEF Wheel PBRAppearance {
                                      baseColor 0.93 0.423 0
                                      metalness 0.4
                                      emissiveColor 0.53 0.023 0
                                    }
                                    geometry DEF wheel Cylinder {
                                      height 0.03
                                      radius 0.05
                                    }
                                  }
                                ]
                                boundingObject USE wheel
                                physics Physics {
                                  density -1
                                  mass 1
                                }
                              }
                            }
                          ]
                        }
                      ]
                      boundingObject USE Hip_link
                      physics Physics {
                        density -1
                        mass 0.5
                        centerOfMass [
                          0 -0.22 0
                        ]
                      }
                    }
                  }
                ]
              }
            ]
            boundingObject USE Hip_link
            physics Physics {
              density -1
              mass 0.5
              centerOfMass [
                0 0 0
              ]
            }
          }
        }
      ]
    }
    DEF RIGHT_LEG Transform {
      translation 0 0 0.125
      children [
        HingeJoint {
          jointParameters HingeJointParameters {
            axis 0 0 1
          }
          device [
            PositionSensor {
              name "right_hip_encoder"
            }
            RotationalMotor {
              name "right_hip_motor"
              maxVelocity 23.5
              maxTorque 35
            }
          ]
          endPoint DEF hip_link Solid {
            rotation 0 0 1 0
            children [
              USE Hip_link
              USE Hip_Motor_Transform
              Transform {
                translation 0 -0.22 0
                children [
                  HingeJoint {
                    jointParameters HingeJointParameters {
                      axis 0 0 1
                    }
                    device [
                      PositionSensor {
                        name "right_keen_encoder"
                      }
                      RotationalMotor {
                        name "right_keen_motor"
                        maxVelocity 23.5
                        maxTorque 35
                      }
                    ]
                    endPoint Solid {
                      rotation 0 0 1 0
                      children [
                        Solid {
                          children [
                            USE Hip_Motor_Transform
                          ]
                          name "solid(1)"
                          boundingObject USE Hip_Motor_Transform
                          physics Physics {
                            density -1
                            mass 0.1
                          }
                        }
                        USE Hip_link
                        Transform {
                          translation 0 -0.22 0
                          rotation 1 0 0 -0.000795307179585869
                          children [
                            USE Hip_Motor_Transform
                          ]
                        }
                        Transform {
                          translation 0 -0.11 0
                          children [
                            HingeJoint {
                              jointParameters HingeJointParameters {
                                axis 0 0 1
                                anchor 0 -0.11 0
                              }
                              device [
                                Brake {
                                  name "right_brake"
                                }
                                PositionSensor {
                                  name "right_wheel_encoder"
                                }
                                RotationalMotor {
                                  name "right_wheel_motor"
                                  maxVelocity 23.5
                                  maxTorque 35
                                }
                              ]
                              endPoint Solid {
                                translation 0 -0.11 0.024999999999999988
                                rotation 1 3.92679496395749e-17 1.570717985582996e-16 1.57
                                children [
                                  Shape {
                                    appearance USE Wheel
                                    geometry DEF wheel Cylinder {
                                      height 0.03
                                      radius 0.05
                                    }
                                  }
                                ]
                                boundingObject USE wheel
                                physics Physics {
                                  density -1
                                  mass 1
                                }
                              }
                            }
                          ]
                        }
                      ]
                      boundingObject USE Hip_link
                      physics Physics {
                        density -1
                        mass 0.5
                        centerOfMass [
                          0 -0.22 0
                        ]
                      }
                    }
                  }
                ]
              }
              Shape {
              }
            ]
            name "solid(1)"
            boundingObject USE Hip_link
            physics Physics {
              density -1
              mass 0.5
              centerOfMass [
                0 0 0
              ]
            }
          }
        }
      ]
    }
    DEF BODY Shape {
      appearance PBRAppearance {
        roughness 0.5
        metalness 0.5
      }
      geometry Box {
        size 0.15 0.1 0.23
      }
    }
  ]
  name "MiniNezha"
  contactMaterial "body"
  boundingObject USE BODY
  physics Physics {
    density -1
    mass 5
    centerOfMass [
      0 0 0
    ]
  }
  controller "my_controller_python"
}
