#VRML_SIM R2020a utf8
WorldInfo {
  basicTimeStep 16
}
Viewpoint {
  orientation 0.7586813756903381 -0.6453132176163057 -0.08929401631860176 5.922378410282784
  position 1.3223972960476296 1.0975738397542614 2.527052493252285
  follow "MiniNezha"
  followSmoothness 0
}
TexturedBackground {
}
TexturedBackgroundLight {
}
Floor {
}
Robot {
  translation 0.27 0.49 0
  rotation 0 0 1 0
  children [
    GPS {
    }
    Gyro {
    }
    InertialUnit {
      name "inertial_unit"
    }
    DEF LEFT_LEG Transform {
      translation 0 0 -0.125
      children [
        HingeJoint {
          jointParameters HingeJointParameters {
            axis 0 0 1
          }
          device [
            PositionSensor {
              name "left_hip_encoder"
            }
            RotationalMotor {
              name "left_hip_motor"
              maxVelocity 23.5
              maxTorque 35
            }
          ]
          endPoint DEF hip_link Solid {
            translation -1.0311498431386323e-05 1.1853529323604264e-05 5.136538708261363e-09
            rotation 0.7544000485867818 0.6564149348484377 4.2741343522005795e-07 5.847637912734942e-07
            children [
              DEF Hip_motor_shape Transform {
                rotation 1 0 0 1.57
                children [
                  Shape {
                    geometry Cylinder {
                      height 0.03
                      radius 0.02
                    }
                  }
                ]
              }
              DEF Hip_link Transform {
                translation 0 -0.11 0
                children [
                  Shape {
                    appearance PBRAppearance {
                      baseColor 0 0 0
                      roughness 0.5
                      metalness 0.5
                    }
                    geometry Box {
                      size 0.02 0.22 0.02
                    }
                  }
                ]
              }
              Transform {
                translation 0 -0.22 0
                children [
                  HingeJoint {
                    jointParameters HingeJointParameters {
                      axis 0 0 1
                    }
                    device [
                      PositionSensor {
                        name "left_keen_encoder"
                      }
                      RotationalMotor {
                        name "left_keen_motor"
                        maxVelocity 23.5
                        maxTorque 35
                      }
                    ]
                    endPoint Solid {
                      rotation 0 0 1 0
                      children [
                        Transform {
                          translation 0 -0.22 0
                          rotation 1 0 0 1.57
                          children [
                            DEF Motor_Shape Shape {
                              geometry Cylinder {
                                height 0.03
                                radius 0.02
                              }
                            }
                          ]
                        }
                        DEF Keen_motor_shape Transform {
                          rotation 1 0 0 1.57
                          children [
                            Shape {
                              geometry Cylinder {
                                height 0.03
                                radius 0.02
                              }
                            }
                          ]
                        }
                        DEF Keen_link Transform {
                          translation 0 -0.11 0
                          children [
                            Shape {
                              appearance PBRAppearance {
                                baseColor 0 0 0
                                roughness 0.5
                                metalness 0.5
                              }
                              geometry Box {
                                size 0.02 0.22 0.02
                              }
                            }
                          ]
                        }
                        Transform {
                          translation 0 -0.11 0
                          children [
                            HingeJoint {
                              jointParameters HingeJointParameters {
                                axis 0 0 1
                                anchor 0 -0.11 0
                              }
                              device [
                                DEF left_wheel_encoder PositionSensor {
                                  name "left_wheel_encoder"
                                }
                                RotationalMotor {
                                  name "left_wheel_motor"
                                  maxVelocity 23.5
                                  maxTorque 35
                                }
                              ]
                              endPoint Solid {
                                translation 0 -0.11 -0.025000000000000015
                                rotation 1 7.853589927914979e-17 -7.853589927914979e-17 1.57
                                children [
                                  DEF wheel Shape {
                                    appearance PBRAppearance {
                                      baseColor 1 0 0
                                      roughness 0.5
                                      metalness 0.5
                                    }
                                    geometry DEF wheel Cylinder {
                                      height 0.03
                                      radius 0.05
                                    }
                                  }
                                ]
                                boundingObject USE wheel
                                physics Physics {
                                  density -1
                                  mass 1
                                }
                              }
                            }
                          ]
                        }
                      ]
                      boundingObject USE Keen_motor_shape
                      physics Physics {
                        density -1
                        mass 0.1
                        centerOfMass [
                          0 -0.22 0
                        ]
                      }
                    }
                  }
                ]
              }
              Shape {
              }
            ]
            boundingObject USE Hip_motor_shape
            physics Physics {
              density -1
              mass 0.1
              centerOfMass [
                0 0 0
              ]
            }
          }
        }
      ]
    }
    DEF RIGHT_LEG Transform {
      translation 0 0 0.125
      children [
        HingeJoint {
          jointParameters HingeJointParameters {
            axis 0 0 1
          }
          device [
            PositionSensor {
              name "right_hip_encoder"
            }
            RotationalMotor {
              name "right_hip_motor"
              maxVelocity 23.5
              maxTorque 35
            }
          ]
          endPoint DEF hip_link Solid {
            translation -7.490386524828039e-06 1.7845785698466682e-05 2.5947286801664134e-06
            rotation -0.9992183949954672 0.039529724275496905 -1.1771243453057986e-06 1.5231290267921623e-06
            children [
              USE Hip_motor_shape
              DEF Hip_link Transform {
                translation 0 -0.11 0
                children [
                  Shape {
                    appearance PBRAppearance {
                      baseColor 0 0 0
                      roughness 0.5
                      metalness 0.5
                    }
                    geometry Box {
                      size 0.02 0.22 0.02
                    }
                  }
                ]
              }
              Transform {
                translation 0 -0.22 0
                children [
                  HingeJoint {
                    jointParameters HingeJointParameters {
                      axis 0 0 1
                    }
                    device [
                      PositionSensor {
                        name "right_keen_encoder"
                      }
                      RotationalMotor {
                        name "right_keen_motor"
                        maxVelocity 23.5
                        maxTorque 35
                      }
                    ]
                    endPoint Solid {
                      translation 1.2261248381270289e-05 1.6065078163967865e-05 -1.1195204624447895e-08
                      rotation -0.7939420595358966 0.6079934260334308 -1.731979270997535e-07 5.280984981855572e-07
                      children [
                        Transform {
                          translation 0 -0.22 0
                          rotation 1 0 0 1.57
                          children [
                            USE Motor_Shape
                          ]
                        }
                        USE Keen_motor_shape
                        DEF Keen_link Transform {
                          translation 0 -0.11 0
                          children [
                            Shape {
                              appearance PBRAppearance {
                                baseColor 0 0 0
                                roughness 0.5
                                metalness 0.5
                              }
                              geometry Box {
                                size 0.02 0.22 0.02
                              }
                            }
                          ]
                        }
                        Transform {
                          translation 0 -0.11 0
                          children [
                            HingeJoint {
                              jointParameters HingeJointParameters {
                                axis 0 0 1
                                anchor 0 -0.11 0
                              }
                              device [
                                PositionSensor {
                                  name "right_wheel_encoder"
                                }
                                RotationalMotor {
                                  name "right_wheel_motor"
                                  maxVelocity 23.5
                                  maxTorque 35
                                }
                              ]
                              endPoint Solid {
                                translation 0 -0.11 0.024999999999999988
                                rotation 1 3.92679496395749e-17 1.570717985582996e-16 1.57
                                children [
                                  DEF wheel Shape {
                                    appearance PBRAppearance {
                                      baseColor 1 0 0
                                      roughness 0.5
                                      metalness 0.5
                                    }
                                    geometry DEF wheel Cylinder {
                                      height 0.03
                                      radius 0.05
                                    }
                                  }
                                ]
                                boundingObject USE wheel
                                physics Physics {
                                  density -1
                                  mass 1
                                }
                              }
                            }
                          ]
                        }
                      ]
                      boundingObject USE Keen_motor_shape
                      physics Physics {
                        density -1
                        mass 0.1
                        centerOfMass [
                          0 -0.22 0
                        ]
                      }
                    }
                  }
                ]
              }
              Shape {
              }
            ]
            name "solid(1)"
            boundingObject USE Hip_motor_shape
            physics Physics {
              density -1
              mass 0.1
              centerOfMass [
                0 0 0
              ]
            }
          }
        }
      ]
    }
    DEF BODY Shape {
      appearance PBRAppearance {
        roughness 0.1
        metalness 0.8
      }
      geometry Box {
        size 0.15 0.1 0.23
      }
    }
  ]
  name "MiniNezha"
  boundingObject USE BODY
  physics Physics {
    density -1
    mass 5
    centerOfMass [
      0 0 0
    ]
  }
  controller "my_controller_python"
}
