#VRML_SIM R2020a utf8
WorldInfo {
  info [
    "This demonstration shows a DJI Mavic 2 PRO flying over a rural area."
    "After the drone has taken off, you can control it with the keyboard of your computer."
  ]
  title "DJI Mavic 2 PRO demo"
  basicTimeStep 16
  defaultDamping Damping {
    linear 0.5
    angular 0.5
  }
}
Viewpoint {
  orientation 0.11321982214764523 0.9547532567266109 0.2750045284041446 3.7349309028886575
  position -27.49363205256295 9.009095488065379 -11.477295148586649
  near 0.2
  follow "MiniNezha"
  followType "None"
  followSmoothness 0.2
}
TexturedBackground {
  luminosity 3
}
TexturedBackgroundLight {
}
Floor {
  size 400 400
  tileSize 6 6
  appearance SandyGround {
  }
}
Robot {
  translation 2.93606 0 6.05729
  rotation 0 1 0 -1.8325953071795862
  children [
    SliderJoint {
      jointParameters JointParameters {
        position 6.2462399999999985
      }
      device [
        PositionSensor {
        }
        LinearMotor {
        }
      ]
      endPoint Solid {
        translation 0 0 6.2462399999999985
        rotation 0 0 1 -1.5708003061004252
        children [
          Shape {
            geometry Cylinder {
              radius 0.05
            }
          }
        ]
      }
    }
    Shape {
      appearance PBRAppearance {
      }
    }
  ]
  controller "linear"
}
CrashBarrier {
  translation -15.2429 -1.18637e-05 2.52816
  rotation 3.0578999999772855e-06 0.9999999999925719 2.3464099999825706e-06 1.309
  name "crash barrier(1)"
  poleAppearance PBRAppearance {
    roughness 0.7
    IBLStrength 2
  }
  path [
    0 0 0
    2.1 0 0
  ]
  enableBoundingObject TRUE
}
Road {
  translation -43.8 0.01 -9.2
  rotation 0 1 0 1.1781
  width 1
  numberOfLanes 1
  rightBorder FALSE
  leftBorder FALSE
  wayPoints [
    0 0 0
    0 0 100
    200 0 200
  ]
  splineSubdivision 8
  appearance NULL
}
WoodenBox {
  translation -23.5212 0.2 -1.30482
  rotation -4.450439999940937e-06 0.9999999999867288 2.5953599999655566e-06 -1.8325953071795862
  name "wooden box(1)"
  size 0.3 0.3 0.3
}
Road {
  translation -43.8 0.012 -9.2
  rotation 0 1 0 1.1781
  name "road(1)"
  width 1.5
  numberOfLanes 1
  rightBorder FALSE
  leftBorder FALSE
  wayPoints [
    0 0 0
    0 0 100
    200 0 200
  ]
  splineSubdivision 8
}
CrashBarrier {
  translation -4.71204 -2.50961e-05 5.34955
  rotation 3.0578999999772855e-06 0.9999999999925719 2.3464099999825706e-06 1.309
  name "crash barrier(2)"
  poleAppearance PBRAppearance {
    roughness 0.7
    IBLStrength 2
  }
  path [
    0 0 0
    2.1 0 0
  ]
  enableBoundingObject TRUE
}
WoodenBox {
  translation -20.1322 0.2 -0.18
  rotation -0.9351132545462786 -0.25056306820553154 -0.25056206820525934 1.63783
  name "wooden box(2)"
  size 0.3 0.3 0.3
}
SmallManor {
  translation -50.35 0 -11.25
  rotation 0 1 0 4.32
}
TeslaModel3Simple {
  translation -41.5139 0.31 -4.34169
  rotation 0 -1 0 -1.309
  color 1 1 1
}
Pine {
  translation -14.0083 0 14.4828
  rotation 0 1 0 3.14159
}
Pine {
  translation -19.6195 0 24.3783
  rotation 0 1 0 2.87979
  name "pine tree(1)"
}
Pine {
  translation -10.6926 0 25.1339
  name "pine tree(4)"
}
Pine {
  translation -23.6341 0 -9.1421
  name "pine tree(5)"
}
Pine {
  translation -26.6328 0 7.1707
  name "pine tree(6)"
}
Pine {
  translation -14.6876 0 -10.9509
  rotation 0 1 0 -2.618
  name "pine tree(2)"
}
Forest {
  translation 0 -0.01 0
  shape [
    200 200
    200 0
    50 0
    50 50
    -50 50
    -50 -50
    50 -50
    50 0
    200 0
    200 -200
    -200 -200
    -200 200
  ]
  density 0.01
  type "cherry tree"
  randomSeed 1
  maxHeight 12
  minHeight 6
  maxRadius 6
  minRadius 3
}
Robot {
  translation -24.317147079221108 0.4681217103753843 -1.410696421433134
  rotation -0.00047204075815273126 0.9975534191516165 0.06990674585790538 -0.015711480358177883
  children [
    GPS {
    }
    Gyro {
    }
    InertialUnit {
      name "inertial_unit"
    }
    DEF LEFT_LEG Transform {
      translation 0 0 -0.125
      children [
        HingeJoint {
          jointParameters HingeJointParameters {
            position -0.3056820329394645
            axis 0 0 1
          }
          device [
            PositionSensor {
              name "left_hip_encoder"
            }
            RotationalMotor {
              name "left_hip_motor"
              maxVelocity 23.5
              maxTorque 35
            }
          ]
          endPoint Solid {
            rotation 0 0 -1 0.3056820329394647
            children [
              DEF Hip_Motor_Transform Transform {
                rotation 1 0 0 1.57
                children [
                  DEF Motor_Shape Shape {
                    appearance DEF Motor_Color PBRAppearance {
                      baseColor 0.9 0.9 0.9
                      metalness 0.2
                    }
                    geometry Cylinder {
                      height 0.03
                      radius 0.02
                    }
                  }
                ]
              }
              DEF Hip_link Transform {
                translation 0 -0.11 0
                children [
                  Shape {
                    appearance PBRAppearance {
                      baseColor 0.93 0.423 0
                      metalness 0.4
                      emissiveColor 0.53 0.023 0
                    }
                    geometry Box {
                      size 0.02 0.22 0.02
                    }
                  }
                ]
              }
              Transform {
                translation 0 -0.22 0
                children [
                  HingeJoint {
                    jointParameters HingeJointParameters {
                      position 0.6053030778271269
                      axis 0 0 1
                    }
                    device [
                      PositionSensor {
                        name "left_keen_encoder"
                      }
                      RotationalMotor {
                        name "left_keen_motor"
                        maxVelocity 23.5
                        maxTorque 35
                      }
                    ]
                    endPoint Solid {
                      rotation 0 0 1 0.6053030778271269
                      children [
                        Solid {
                          rotation 1 0 0 0
                          children [
                            USE Hip_Motor_Transform
                          ]
                          name "solid(1)"
                          boundingObject USE Hip_Motor_Transform
                          physics Physics {
                            density -1
                            mass 0.1
                          }
                        }
                        Transform {
                          translation 0 -0.22 0
                          rotation 1 0 0 -0.000795307179585869
                          children [
                            USE Hip_Motor_Transform
                          ]
                        }
                        USE Hip_link
                        Transform {
                          translation 0 -0.11 0
                          children [
                            HingeJoint {
                              jointParameters HingeJointParameters {
                                position -368.56072220326564
                                axis 0 0 1
                                anchor 0 -0.11 0
                              }
                              device [
                                Brake {
                                  name "left_brake"
                                }
                                DEF left_wheel_encoder PositionSensor {
                                  name "left_wheel_encoder"
                                }
                                RotationalMotor {
                                  name "left_wheel_motor"
                                  maxVelocity 23.5
                                  maxTorque 35
                                }
                              ]
                              endPoint Solid {
                                translation 0 -0.11 -0.025000000000000015
                                rotation -0.35812552829524424 -0.6599439034016754 -0.660469643773438 3.8298886990348278
                                children [
                                  DEF wheel Shape {
                                    appearance PBRAppearance {
                                      baseColor 1 0 0
                                      roughness 0.5
                                      metalness 0.5
                                    }
                                    geometry DEF wheel Cylinder {
                                      height 0.03
                                      radius 0.05
                                    }
                                  }
                                ]
                                boundingObject USE wheel
                                physics Physics {
                                  density -1
                                  mass 1
                                }
                                linearVelocity -0.00013446042591052016 -8.012100816314646e-11 -2.1078037298198265e-06
                                angularVelocity -4.2199705202995426e-05 -5.030256494455109e-07 0.0026922458958863237
                              }
                            }
                          ]
                        }
                      ]
                      boundingObject USE Hip_link
                      physics Physics {
                        density -1
                        mass 0.5
                        centerOfMass [
                          0 -0.22 0
                        ]
                      }
                      linearVelocity -0.00013448112862692377 -2.6195578501876618e-09 -2.1134851973861362e-06
                      angularVelocity -4.290403813955096e-09 -5.005283114504622e-07 2.3666170503646132e-07
                    }
                  }
                ]
              }
            ]
            boundingObject USE Hip_link
            physics Physics {
              density -1
              mass 0.5
              centerOfMass [
                0 0 0
              ]
            }
            linearVelocity -0.0001345723254242915 3.424056621278789e-10 -2.1088119861814473e-06
            angularVelocity -4.300687538107457e-09 -5.005321549854549e-07 2.366624133584893e-07
          }
        }
      ]
    }
    DEF RIGHT_LEG Transform {
      translation 0 0 0.125
      children [
        HingeJoint {
          jointParameters HingeJointParameters {
            position -0.3056820329306218
            axis 0 0 1
          }
          device [
            PositionSensor {
              name "right_hip_encoder"
            }
            RotationalMotor {
              name "right_hip_motor"
              maxVelocity 23.5
              maxTorque 35
            }
          ]
          endPoint DEF hip_link Solid {
            rotation 0 0 -1 0.3056820329306221
            children [
              USE Hip_link
              USE Hip_Motor_Transform
              Transform {
                translation 0 -0.22 0
                children [
                  HingeJoint {
                    jointParameters HingeJointParameters {
                      position 0.6053030772756511
                      axis 0 0 1
                    }
                    device [
                      PositionSensor {
                        name "right_keen_encoder"
                      }
                      RotationalMotor {
                        name "right_keen_motor"
                        maxVelocity 23.5
                        maxTorque 35
                      }
                    ]
                    endPoint Solid {
                      rotation 0 0 1 0.6053030772756514
                      children [
                        Solid {
                          children [
                            USE Hip_Motor_Transform
                          ]
                          name "solid(1)"
                          boundingObject USE Hip_Motor_Transform
                          physics Physics {
                            density -1
                            mass 0.1
                          }
                        }
                        USE Hip_link
                        Transform {
                          translation 0 -0.22 0
                          rotation 1 0 0 -0.000795307179585869
                          children [
                            USE Hip_Motor_Transform
                          ]
                        }
                        Transform {
                          translation 0 -0.11 0
                          children [
                            HingeJoint {
                              jointParameters HingeJointParameters {
                                position -365.65734313365135
                                axis 0 0 1
                                anchor 0 -0.11 0
                              }
                              device [
                                Brake {
                                  name "right_brake"
                                }
                                PositionSensor {
                                  name "right_wheel_encoder"
                                }
                                RotationalMotor {
                                  name "right_wheel_motor"
                                  maxVelocity 23.5
                                  maxTorque 35
                                }
                              ]
                              endPoint Solid {
                                translation 0 -0.11 0.02499999999999998
                                rotation 0.7063522662994123 -0.5003336203350105 -0.5007322081274036 1.910888997466216
                                children [
                                  DEF wheel Shape {
                                    appearance PBRAppearance {
                                      baseColor 1 0 0
                                      roughness 0.5
                                      metalness 0.5
                                    }
                                    geometry DEF wheel Cylinder {
                                      height 0.03
                                      radius 0.05
                                    }
                                  }
                                ]
                                boundingObject USE wheel
                                physics Physics {
                                  density -1
                                  mass 1
                                }
                                linearVelocity -0.000134610573948071 9.589079088817187e-11 -2.109762111900771e-06
                                angularVelocity -4.224687511723337e-05 -4.916101837866992e-07 0.002695250552325415
                              }
                            }
                          ]
                        }
                      ]
                      boundingObject USE Hip_link
                      physics Physics {
                        density -1
                        mass 0.5
                        centerOfMass [
                          0 -0.22 0
                        ]
                      }
                      linearVelocity -0.00013460625104407356 -2.4715124784848663e-09 -2.1151772523196797e-06
                      angularVelocity -4.35837174376957e-09 -5.005362985042031e-07 2.366604065226199e-07
                    }
                  }
                ]
              }
              Shape {
              }
            ]
            name "solid(1)"
            boundingObject USE Hip_link
            physics Physics {
              density -1
              mass 0.5
              centerOfMass [
                0 0 0
              ]
            }
            linearVelocity -0.00013469744514843515 4.932386595619927e-10 -2.11064966381786e-06
            angularVelocity -4.347657797924402e-09 -5.005322649549949e-07 2.3666168241954713e-07
          }
        }
      ]
    }
    DEF BODY Shape {
      appearance Appearance {
        material Material {
          diffuseColor 0 0.247 0.263
          emissiveColor 0 0.047 0.063
        }
        texture ImageTexture {
          url [
            "sustech1.png"
          ]
        }
        textureTransform TextureTransform {
        }
      }
      geometry Box {
        size 0.15 0.1 0.23
      }
    }
  ]
  name "MiniNezha"
  contactMaterial "body"
  boundingObject USE BODY
  physics Physics {
    density -1
    mass 5
    centerOfMass [
      0 0 0
    ]
  }
  controller "my_controller_python"
  linearVelocity -0.0001346348800770214 4.1803873486511376e-10 -2.109730734770153e-06
  angularVelocity -4.32404847513057e-09 -5.005323299894593e-07 2.366625262254426e-07
}
Solid {
  translation -11.1065 0 2.12198
  rotation 0 1 0 -0.261795307179586
  scale 1.5 1.5 1.5
  children [
    Solid {
      translation 0 -0.001395819864535408 0
      children [
        DEF ramp Shape {
          appearance PBRAppearance {
            roughness 1
            metalness 0
            name "DefaultMaterial"
          }
          geometry IndexedFaceSet {
            coord Coordinate {
              point [
                1.97007 0.217516 0.7, 1.97007 0.217516 0, 2.78185 -2.71051e-17 0, 2.78185 -2.71051e-17 0.7, 0.15 0 0, 0 0 0.7, 0 0 0, 0 0 0.7, 0.965926 0.258819 0.7, 0 0 0, 0.965926 0.258819 0, 0.965926 0.258819 0, 0.15 0 0, 0 0 0, 0.96178 0.217516 0, 0.96178 0.217516 0, 0.15 0 0.7, 0.15 0 0, 1.96593 0.258819 -2.1684e-16, 2.93185 9.75782e-16 -2.1684e-16, 2.78185 -2.71051e-17 0, 1.97007 0.217516 0, 0.15 0 0.7, 0.15 0 0.7, 0.965926 0.258819 0.7, 0 0 0.7, 0.96178 0.217516 0.7, 0.96178 0.217516 0.7, 2.93185 9.75782e-16 0.7, 1.96593 0.258819 0.7, 2.78185 -2.71051e-17 0.7, 1.97007 0.217516 0.7, 1.96593 0.258819 -2.1684e-16, 2.93185 9.75782e-16 0.7, 2.93185 9.75782e-16 -2.1684e-16, 1.96593 0.258819 0.7, 2.93185 9.75782e-16 -2.1684e-16, 2.78185 -2.71051e-17 0.7, 2.78185 -2.71051e-17 0, 2.93185 9.75782e-16 0.7, 1.97007 0.217516 0, 0.96178 0.217516 0.7, 0.96178 0.217516 0, 1.97007 0.217516 0.7, 0.965926 0.258819 0.7, 1.96593 0.258819 0.7, 0.965926 0.258819 0, 1.96593 0.258819 -2.1684e-16
              ]
            }
            normal Normal {
              vector [
                -0.258819 -0.965926 0, -0.258819 -0.965926 0, -0.258819 -0.965926 0, -0.258819 -0.965926 0, 0 -1 0, 0 -1 0, 0 -1 0, -0.258819 0.965926 0, -0.258819 0.965926 0, -0.258819 0.965926 0, -0.258819 0.965926 0, 0 0 -1, 0 0 -1, 0 0 -1, 0 0 -1, 0.258819 -0.965926 0, 0.258819 -0.965926 0, 0.258819 -0.965926 0, -1.4456e-15 -5.39506e-15 -1, -1.4456e-15 -5.39506e-15 -1, -1.4456e-15 -5.39506e-15 -1, -1.4456e-15 -5.39506e-15 -1, 0 -1 0, 0 0 1, 0 0 1, 0 0 1, 0 0 1, 0.258819 -0.965926 0, 0 0 1, 0 0 1, 0 0 1, 0 0 1, 0.258819 0.965926 0, 0.258819 0.965926 0, 0.258819 0.965926 0, 0.258819 0.965926 0, 6.68591e-15 -1 0, 6.68591e-15 -1 0, 6.68591e-15 -1 0, 6.68591e-15 -1 0, 0 -1 0, 0 -1 0, 0 -1 0, 0 -1 0, 0 1 0, 0 1 0, 0 1 0, 0 1 0
              ]
            }
            coordIndex [
              0, 1, 2, -1, 3, 0, 2, -1, 4, 5, 6, -1, 7, 8, 9, -1, 8, 10, 9, -1, 11, 12, 13, -1, 11, 14, 12, -1, 15, 16, 17, -1, 18, 19, 20, -1, 21, 18, 20, -1, 4, 22, 5, -1, 23, 24, 25, -1, 26, 24, 23, -1, 15, 27, 16, -1, 28, 29, 30, -1, 29, 31, 30, -1, 32, 33, 34, -1, 32, 35, 33, -1, 36, 37, 38, -1, 36, 39, 37, -1, 11, 21, 14, -1, 40, 41, 42, -1, 11, 18, 21, -1, 43, 41, 40, -1, 29, 24, 26, -1, 31, 29, 26, -1, 44, 45, 46, -1, 45, 47, 46, -1
            ]
          }
        }
      ]
      name ""
      boundingObject USE ramp
      physics Physics {
      }
      linearVelocity 0 -6.968552484806683e-16 0
    }
  ]
  name "<STL_BINARY>"
}
