#VRML_SIM R2020b utf8
WorldInfo {
  info [
    "This demonstration shows a DJI Mavic 2 PRO flying over a rural area."
    "After the drone has taken off, you can control it with the keyboard of your computer."
  ]
  title "DJI Mavic 2 PRO demo"
  basicTimeStep 16
  defaultDamping Damping {
    linear 0.5
    angular 0.5
  }
  coordinateSystem "NUE"
}
Viewpoint {
  orientation 0.0162763003703429 0.9838242522244327 0.1783954113235267 2.8188193524123535
  position 2.3801906590296587 7.833648119992371 -14.850043193327478
  near 0.2
  followSmoothness 0.2
}
TexturedBackground {
  luminosity 3
}
TexturedBackgroundLight {
}
Floor {
  size 400 400
  tileSize 6 6
  appearance SandyGround {
  }
}
CrashBarrier {
  translation -15.2429 -1.18637e-05 2.52816
  rotation 3.0578999999772855e-06 0.9999999999925719 2.3464099999825706e-06 1.309
  name "crash barrier(1)"
  poleAppearance PBRAppearance {
    roughness 0.7
    IBLStrength 2
  }
  path [
    0 0 0
    2.1 0 0
  ]
  enableBoundingObject TRUE
}
Road {
  translation -43.8 0.01 -9.2
  rotation 0 1 0 1.1781
  width 1
  numberOfLanes 1
  rightBorder FALSE
  leftBorder FALSE
  wayPoints [
    0 0 0
    0 0 100
    200 0 200
  ]
  splineSubdivision 8
  appearance NULL
}
WoodenBox {
  translation -23.5212 0.2 -1.30482
  rotation -4.450439999940937e-06 0.9999999999867288 2.5953599999655566e-06 -1.8325953071795862
  name "wooden box(1)"
  size 0.3 0.3 0.3
}
Road {
  translation -43.8 0.012 -9.2
  rotation 0 1 0 1.1781
  name "road(1)"
  width 1.5
  numberOfLanes 1
  rightBorder FALSE
  leftBorder FALSE
  wayPoints [
    0 0 0
    0 0 100
    200 0 200
  ]
  splineSubdivision 8
}
CrashBarrier {
  translation -4.71204 -2.50961e-05 5.34955
  rotation 3.0578999999772855e-06 0.9999999999925719 2.3464099999825706e-06 1.309
  name "crash barrier(2)"
  poleAppearance PBRAppearance {
    roughness 0.7
    IBLStrength 2
  }
  path [
    0 0 0
    2.1 0 0
  ]
  enableBoundingObject TRUE
}
WoodenBox {
  translation -20.1322 0.2 -0.18
  rotation -0.9351132545462786 -0.25056306820553154 -0.25056206820525934 1.63783
  name "wooden box(2)"
  size 0.3 0.3 0.3
}
SmallManor {
  translation -50.35 0 -11.25
  rotation 0 1 0 4.32
}
TeslaModel3Simple {
  translation -41.5139 0.31 -4.34169
  rotation 0 -1 0 -1.309
  color 1 1 1
}
Pine {
  translation -14.0083 0 14.4828
  rotation 0 1 0 3.14159
}
Pine {
  translation -19.6195 0 24.3783
  rotation 0 1 0 2.87979
  name "pine tree(1)"
}
Pine {
  translation -10.6926 0 25.1339
  name "pine tree(4)"
}
Pine {
  translation -23.6341 0 -9.1421
  name "pine tree(5)"
}
Pine {
  translation -26.6328 0 7.1707
  name "pine tree(6)"
}
Pine {
  translation -14.6876 0 -10.9509
  rotation 0 1 0 -2.618
  name "pine tree(2)"
}
Forest {
  translation 0 -0.01 0
  shape [
    200 200
    200 0
    50 0
    50 50
    -50 50
    -50 -50
    50 -50
    50 0
    200 0
    200 -200
    -200 -200
    -200 200
  ]
  density 0.01
  type "cherry tree"
  randomSeed 1
  maxHeight 12
  minHeight 6
  maxRadius 6
  minRadius 3
}
Robot {
  translation -24.14 1.09001 -2.26
  rotation 1 0 0 4.692820414042842e-06
  scale 0.4 0.4 0.4
  children [
    DEF externBody Shape {
      geometry Sphere {
        radius 0.1
      }
      castShadows FALSE
    }
    HingeJoint {
      jointParameters HingeJointParameters {
        position -0.009007949460809723
      }
      endPoint Solid {
        translation 0 -1.4999392741748894 0.013511765379571291
        rotation -1 0 0 0.00900794946081806
        children [
          DEF externBall Shape {
            appearance PBRAppearance {
              roughness 0.5
            }
            geometry Sphere {
              radius 0.2
              subdivision 3
            }
            castShadows FALSE
          }
          Transform {
            translation 0 0.75 0
            children [
              Shape {
                appearance PBRAppearance {
                  baseColor 1 0 0
                  roughness 0.5
                  metalness 0
                  IBLStrength 2
                }
                geometry Cylinder {
                  height 1.5
                  radius 0.01
                }
                castShadows FALSE
              }
            ]
          }
        ]
        boundingObject USE externBall
        physics Physics {
          density -1
          mass 2
        }
        linearVelocity 0 -8.837473327732062e-05 -0.008284196704830089
        angularVelocity 0.013807781667609594 0 0
      }
    }
  ]
  name "robot(1)"
  boundingObject USE externBody
}
WoodenBox {
  translation -21.7521 0.199999 -0.734216
  rotation 0.5773529358523396 -0.5773479358528951 -0.5773499358526729 2.0944
  size 0.3 0.3 0.3
}
Robot {
  translation -10.50978020483104 0.6770367039058213 2.8579977542854658
  rotation -0.014966194348443275 0.9818797597521723 0.18891307634925888 -0.25780905143441246
  children [
    GPS {
    }
    Gyro {
    }
    InertialUnit {
      name "inertial_unit"
    }
    DEF LEFT_LEG Transform {
      translation 0 0 -0.125
      children [
        HingeJoint {
          jointParameters HingeJointParameters {
            position -0.21570225973163465
            axis 0 0 1
          }
          device [
            PositionSensor {
              name "left_hip_encoder"
            }
            RotationalMotor {
              name "left_hip_motor"
              maxVelocity 23.5
              maxTorque 35
            }
          ]
          endPoint DEF hip_link Solid {
            translation -7.53549117380986e-06 1.3785845280412672e-05 5.1365387082614326e-09
            rotation 2.2087908162081906e-06 1.5378731985652447e-06 -0.999999999996378 0.21570225950809846
            children [
              DEF Hip_motor_shape Transform {
                rotation 1 0 0 1.57
                children [
                  Shape {
                    geometry Cylinder {
                      height 0.03
                      radius 0.02
                    }
                  }
                ]
              }
              DEF Hip_link Transform {
                translation 0 -0.11 0
                children [
                  Shape {
                    appearance PBRAppearance {
                      baseColor 0 0 0
                      roughness 0.5
                      metalness 0.5
                    }
                    geometry Box {
                      size 0.02 0.22 0.02
                    }
                  }
                ]
              }
              Transform {
                translation 0 -0.22 0
                children [
                  HingeJoint {
                    jointParameters HingeJointParameters {
                      position 0.4271941434017273
                      axis 0 0 1
                    }
                    device [
                      PositionSensor {
                        name "left_keen_encoder"
                      }
                      RotationalMotor {
                        name "left_keen_motor"
                        maxVelocity 23.5
                        maxTorque 35
                      }
                    ]
                    endPoint Solid {
                      rotation 0 0 1 0.42719414340172684
                      children [
                        Transform {
                          translation 0 -0.22 0
                          rotation 1 0 0 1.57
                          children [
                            DEF Motor_Shape Shape {
                              geometry Cylinder {
                                height 0.03
                                radius 0.02
                              }
                            }
                          ]
                        }
                        DEF Keen_motor_shape Transform {
                          rotation 1 0 0 1.57
                          children [
                            Shape {
                              geometry Cylinder {
                                height 0.03
                                radius 0.02
                              }
                            }
                          ]
                        }
                        DEF Keen_link Transform {
                          translation 0 -0.11 0
                          children [
                            Shape {
                              appearance PBRAppearance {
                                baseColor 0 0 0
                                roughness 0.5
                                metalness 0.5
                              }
                              geometry Box {
                                size 0.02 0.22 0.02
                              }
                            }
                          ]
                        }
                        Transform {
                          translation 0 -0.11 0
                          children [
                            HingeJoint {
                              jointParameters HingeJointParameters {
                                position -21.542610936349437
                                axis 0 0 1
                                anchor 0 -0.11 0
                              }
                              device [
                                DEF left_wheel_encoder PositionSensor {
                                  name "left_wheel_encoder"
                                }
                                RotationalMotor {
                                  name "left_wheel_motor"
                                  maxVelocity 23.5
                                  maxTorque 35
                                }
                              ]
                              endPoint Solid {
                                translation 0 -0.11 -0.02499999999999995
                                rotation -0.15917542100129498 0.6978133830117456 0.6983692918784183 3.4575423185484424
                                children [
                                  DEF wheel Shape {
                                    appearance PBRAppearance {
                                      baseColor 1 0 0
                                      roughness 0.5
                                      metalness 0.5
                                    }
                                    geometry DEF wheel Cylinder {
                                      height 0.03
                                      radius 0.05
                                    }
                                  }
                                ]
                                boundingObject USE wheel
                                physics Physics {
                                  density -1
                                  mass 1
                                }
                                linearVelocity 0.1465439854333479 0.0405709969069729 0.03781306077792016
                                angularVelocity 0.7844215635123645 -0.004683643311914781 -3.034955876114565
                              }
                            }
                          ]
                        }
                      ]
                      boundingObject USE Keen_motor_shape
                      physics Physics {
                        density -1
                        mass 0.1
                        centerOfMass [
                          0 -0.22 0
                        ]
                      }
                      linearVelocity 0.1466043894508383 0.040588236957069944 0.03782859930977615
                      angularVelocity 0.013255644510862545 0.00240319388534652 -0.054048771125955644
                    }
                  }
                ]
              }
              Shape {
              }
            ]
            boundingObject USE Hip_motor_shape
            physics Physics {
              density -1
              mass 0.1
              centerOfMass [
                0 0 0
              ]
            }
            linearVelocity 0.16982590467182543 0.03938476144907866 0.043470199853324565
            angularVelocity 0.013255667597706546 0.002403188165077131 -0.05404883127774509
          }
        }
      ]
    }
    DEF RIGHT_LEG Transform {
      translation 0 0 0.125
      children [
        HingeJoint {
          jointParameters HingeJointParameters {
            position -0.21570220868157092
            axis 0 0 1
          }
          device [
            PositionSensor {
              name "right_hip_encoder"
            }
            RotationalMotor {
              name "right_hip_motor"
              maxVelocity 23.5
              maxTorque 35
            }
          ]
          endPoint DEF hip_link Solid {
            translation -3.4972123550307212e-06 1.903542653135857e-05 2.5947286801663803e-06
            rotation -6.976789307146653e-06 1.0358285807708476e-06 -0.9999999999751257 0.2157022084837828
            children [
              USE Hip_motor_shape
              DEF Hip_link Transform {
                translation 0 -0.11 0
                children [
                  Shape {
                    appearance PBRAppearance {
                      baseColor 0 0 0
                      roughness 0.5
                      metalness 0.5
                    }
                    geometry Box {
                      size 0.02 0.22 0.02
                    }
                  }
                ]
              }
              Transform {
                translation 0 -0.22 0
                children [
                  HingeJoint {
                    jointParameters HingeJointParameters {
                      position 0.42719415138636724
                      axis 0 0 1
                    }
                    device [
                      PositionSensor {
                        name "right_keen_encoder"
                      }
                      RotationalMotor {
                        name "right_keen_motor"
                        maxVelocity 23.5
                        maxTorque 35
                      }
                    ]
                    endPoint Solid {
                      translation 4.503289613613008e-06 1.970140428846436e-05 -1.119520462444765e-08
                      rotation -1.1125912874714185e-06 5.23696210802453e-07 0.9999999999992439 0.4271941508820226
                      children [
                        Transform {
                          translation 0 -0.22 0
                          rotation 1 0 0 1.57
                          children [
                            USE Motor_Shape
                          ]
                        }
                        USE Keen_motor_shape
                        DEF Keen_link Transform {
                          translation 0 -0.11 0
                          children [
                            Shape {
                              appearance PBRAppearance {
                                baseColor 0 0 0
                                roughness 0.5
                                metalness 0.5
                              }
                              geometry Box {
                                size 0.02 0.22 0.02
                              }
                            }
                          ]
                        }
                        Transform {
                          translation 0 -0.11 0
                          children [
                            HingeJoint {
                              jointParameters HingeJointParameters {
                                position -21.60137737748262
                                axis 0 0 1
                                anchor 0 -0.11 0
                              }
                              device [
                                PositionSensor {
                                  name "right_wheel_encoder"
                                }
                                RotationalMotor {
                                  name "right_wheel_motor"
                                  maxVelocity 23.5
                                  maxTorque 35
                                }
                              ]
                              endPoint Solid {
                                translation 0 -0.11 0.024999999999999932
                                rotation -0.13818242709324788 0.7000444612662912 0.700602147508133 3.41643441979343
                                children [
                                  DEF wheel Shape {
                                    appearance PBRAppearance {
                                      baseColor 1 0 0
                                      roughness 0.5
                                      metalness 0.5
                                    }
                                    geometry DEF wheel Cylinder {
                                      height 0.03
                                      radius 0.05
                                    }
                                  }
                                ]
                                boundingObject USE wheel
                                physics Physics {
                                  density -1
                                  mass 1
                                }
                                linearVelocity 0.14728081188646458 0.04078109972879368 0.03800285925648885
                                angularVelocity 0.7883732137959969 -0.004737270350460422 -3.0502400437723014
                              }
                            }
                          ]
                        }
                      ]
                      boundingObject USE Keen_motor_shape
                      physics Physics {
                        density -1
                        mass 0.1
                        centerOfMass [
                          0 -0.22 0
                        ]
                      }
                      linearVelocity 0.1472186102354573 0.04076321222871469 0.03798684733844697
                      angularVelocity 0.013255670730596884 0.002403148077564323 -0.05404872438223568
                    }
                  }
                ]
              }
              Shape {
              }
            ]
            name "solid(1)"
            boundingObject USE Hip_motor_shape
            physics Physics {
              density -1
              mass 0.1
              centerOfMass [
                0 0 0
              ]
            }
            linearVelocity 0.17043907684623558 0.039560370849649466 0.04362831133225528
            angularVelocity 0.013255686590300178 0.002403162940699374 -0.054048796036132184
          }
        }
      ]
    }
    DEF BODY Shape {
      appearance PBRAppearance {
        roughness 0.1
        metalness 0.8
      }
      geometry Box {
        size 0.15 0.1 0.23
      }
    }
  ]
  name "MiniNezha"
  boundingObject USE BODY
  physics Physics {
    density -1
    mass 5
    centerOfMass [
      0 0 0
    ]
  }
  controller "my_controller_python"
  linearVelocity 0.17013076779297903 0.039472003184223114 0.04354880614246865
  angularVelocity 0.013255683673982749 0.0024031792126183896 -0.05404881397528362
}
Solid {
  translation -11.1065 0 2.12198
  rotation 0 1 0 -0.261795307179586
  scale 1.5 1.5 1.5
  children [
    Solid {
      translation 1.3848027029281537e-05 -0.0015589355736550143 -2.9592651845038944e-07
      rotation -0.01992331855723204 0.00017917321170027743 -0.9998014949351832 -8.529562616396135e-05
      children [
        DEF ramp Shape {
          appearance PBRAppearance {
            roughness 1
            metalness 0
            name "DefaultMaterial"
          }
          geometry IndexedFaceSet {
            coord Coordinate {
              point [
                1.97007 0.217516 0.7, 1.97007 0.217516 0, 2.78185 -2.71051e-17 0, 2.78185 -2.71051e-17 0.7, 0.15 0 0, 0 0 0.7, 0 0 0, 0 0 0.7, 0.965926 0.258819 0.7, 0 0 0, 0.965926 0.258819 0, 0.965926 0.258819 0, 0.15 0 0, 0 0 0, 0.96178 0.217516 0, 0.96178 0.217516 0, 0.15 0 0.7, 0.15 0 0, 1.96593 0.258819 -2.1684e-16, 2.93185 9.75782e-16 -2.1684e-16, 2.78185 -2.71051e-17 0, 1.97007 0.217516 0, 0.15 0 0.7, 0.15 0 0.7, 0.965926 0.258819 0.7, 0 0 0.7, 0.96178 0.217516 0.7, 0.96178 0.217516 0.7, 2.93185 9.75782e-16 0.7, 1.96593 0.258819 0.7, 2.78185 -2.71051e-17 0.7, 1.97007 0.217516 0.7, 1.96593 0.258819 -2.1684e-16, 2.93185 9.75782e-16 0.7, 2.93185 9.75782e-16 -2.1684e-16, 1.96593 0.258819 0.7, 2.93185 9.75782e-16 -2.1684e-16, 2.78185 -2.71051e-17 0.7, 2.78185 -2.71051e-17 0, 2.93185 9.75782e-16 0.7, 1.97007 0.217516 0, 0.96178 0.217516 0.7, 0.96178 0.217516 0, 1.97007 0.217516 0.7, 0.965926 0.258819 0.7, 1.96593 0.258819 0.7, 0.965926 0.258819 0, 1.96593 0.258819 -2.1684e-16
              ]
            }
            normal Normal {
              vector [
                -0.258819 -0.965926 0, -0.258819 -0.965926 0, -0.258819 -0.965926 0, -0.258819 -0.965926 0, 0 -1 0, 0 -1 0, 0 -1 0, -0.258819 0.965926 0, -0.258819 0.965926 0, -0.258819 0.965926 0, -0.258819 0.965926 0, 0 0 -1, 0 0 -1, 0 0 -1, 0 0 -1, 0.258819 -0.965926 0, 0.258819 -0.965926 0, 0.258819 -0.965926 0, -1.4456e-15 -5.39506e-15 -1, -1.4456e-15 -5.39506e-15 -1, -1.4456e-15 -5.39506e-15 -1, -1.4456e-15 -5.39506e-15 -1, 0 -1 0, 0 0 1, 0 0 1, 0 0 1, 0 0 1, 0.258819 -0.965926 0, 0 0 1, 0 0 1, 0 0 1, 0 0 1, 0.258819 0.965926 0, 0.258819 0.965926 0, 0.258819 0.965926 0, 0.258819 0.965926 0, 6.68591e-15 -1 0, 6.68591e-15 -1 0, 6.68591e-15 -1 0, 6.68591e-15 -1 0, 0 -1 0, 0 -1 0, 0 -1 0, 0 -1 0, 0 1 0, 0 1 0, 0 1 0, 0 1 0
              ]
            }
            coordIndex [
              0, 1, 2, -1, 3, 0, 2, -1, 4, 5, 6, -1, 7, 8, 9, -1, 8, 10, 9, -1, 11, 12, 13, -1, 11, 14, 12, -1, 15, 16, 17, -1, 18, 19, 20, -1, 21, 18, 20, -1, 4, 22, 5, -1, 23, 24, 25, -1, 26, 24, 23, -1, 15, 27, 16, -1, 28, 29, 30, -1, 29, 31, 30, -1, 32, 33, 34, -1, 32, 35, 33, -1, 36, 37, 38, -1, 36, 39, 37, -1, 11, 21, 14, -1, 40, 41, 42, -1, 11, 18, 21, -1, 43, 41, 40, -1, 29, 24, 26, -1, 31, 29, 26, -1, 44, 45, 46, -1, 45, 47, 46, -1
            ]
          }
        }
      ]
      name ""
      boundingObject USE ramp
      physics Physics {
      }
      linearVelocity -2.601226931611957e-06 -8.636324837148098e-07 -6.777384796011859e-07
      angularVelocity 2.5612763200151484e-06 4.579716257713413e-10 -9.016390871027773e-06
    }
  ]
  name "<STL_BINARY>"
}
Robot {
  translation 1.67323 0 5.65565
  rotation 0 1 0 1.309
  children [
    Solid {
      name "solid(1)"
      boundingObject Shape {
        geometry Cylinder {
          height 0.1
          radius 0.05
        }
      }
    }
    SliderJoint {
      jointParameters JointParameters {
        position -0.0384000000000002
      }
      device [
        PositionSensor {
        }
        LinearMotor {
        }
      ]
      endPoint Solid {
        translation 0 0 -0.0384000000000002
        rotation 0 0 1 -1.5708003061004252
        children [
          Shape {
            geometry Cylinder {
              radius 0.05
            }
          }
        ]
      }
    }
    Shape {
      appearance PBRAppearance {
      }
    }
  ]
  controller "linear"
}
