#VRML_SIM R2021a utf8
WorldInfo {
  CFM 1e-06
  ERP 0.6
  basicTimeStep 8
  coordinateSystem "NUE"
  contactProperties [
    ContactProperties {
      bounce 0
    }
    ContactProperties {
      material1 "body"
      coulombFriction [
        0
      ]
      bounce 0
    }
  ]
}
Viewpoint {
  orientation 0.743963882240224 0.666825578499601 0.04314382668153467 5.876796507324662
  position 0.08181590977861652 0.8073829708721236 0.6765196275900371
  follow "MiniNezha"
  followSmoothness 0
}
TexturedBackground {
}
TexturedBackgroundLight {
}
Floor {
}
Robot {
  translation 0.5778570268411918 0.30114139140572654 -1.506318749736308
  rotation -0.00754781420768318 0.9967114267779952 -0.08068061868168494 0.19295550893507712
  children [
    GPS {
    }
    Gyro {
    }
    InertialUnit {
      name "inertial_unit"
    }
    DEF LEFT_LEG Transform {
      translation 0 0 -0.125
      children [
        HingeJoint {
          jointParameters HingeJointParameters {
            position -0.980491674901105
            axis 0 0 1
          }
          device [
            PositionSensor {
              name "left_hip_encoder"
            }
            RotationalMotor {
              name "left_hip_motor"
              maxVelocity 23.5
              maxTorque 35
            }
          ]
          endPoint Solid {
            rotation 0 0 -1 0.9804916749011049
            children [
              DEF Hip_Motor_Transform Transform {
                rotation 1 0 0 1.57
                children [
                  DEF Motor_Shape Shape {
                    appearance DEF Motor_Color PBRAppearance {
                      baseColor 0.9 0.9 0.9
                      metalness 0.2
                    }
                    geometry Cylinder {
                      height 0.03
                      radius 0.02
                    }
                  }
                ]
              }
              DEF Hip_link Transform {
                translation 0 -0.11 0
                children [
                  Shape {
                    appearance PBRAppearance {
                      baseColor 0 0.247 0.263
                      roughness 0.5
                      metalness 0.5
                      emissiveColor 0 0.047 0.063
                    }
                    geometry Box {
                      size 0.02 0.22 0.02
                    }
                  }
                ]
              }
              Transform {
                translation 0 -0.22 0
                children [
                  HingeJoint {
                    jointParameters HingeJointParameters {
                      position 1.9328672644986566
                      axis 0 0 1
                    }
                    device [
                      PositionSensor {
                        name "left_keen_encoder"
                      }
                      RotationalMotor {
                        name "left_keen_motor"
                        maxVelocity 23.5
                        maxTorque 35
                      }
                    ]
                    endPoint Solid {
                      rotation 0 0 1 1.9328672644986566
                      children [
                        Solid {
                          rotation 1 0 0 0
                          children [
                            USE Hip_Motor_Transform
                          ]
                          name "solid(1)"
                          boundingObject USE Hip_Motor_Transform
                          physics Physics {
                            density -1
                            mass 0.1
                          }
                        }
                        Transform {
                          translation 0 -0.22 0
                          rotation 1 0 0 -0.000795307179585869
                          children [
                            USE Hip_Motor_Transform
                          ]
                        }
                        USE Hip_link
                        Transform {
                          translation 0 -0.11 0
                          children [
                            HingeJoint {
                              jointParameters HingeJointParameters {
                                position -65.00261732346078
                                axis 0 0 1
                                anchor 0 -0.11 0
                              }
                              device [
                                Brake {
                                  name "left_brake"
                                }
                                DEF left_wheel_encoder PositionSensor {
                                  name "left_wheel_encoder"
                                }
                                RotationalMotor {
                                  name "left_wheel_motor"
                                  maxVelocity 23.5
                                  maxTorque 35
                                }
                              ]
                              endPoint Solid {
                                translation 0 -0.11 -0.025000000000000043
                                rotation 0.3493638692469509 -0.6622860997714042 -0.6628137060399258 2.46888061307779
                                children [
                                  TouchSensor {
                                    translation 5.689822171750514e-07 -9.652190158249141e-11 3.484411248422248e-08
                                    rotation -0.9683773314628906 -0.0027012046860677642 -0.24947554469738073 3.3317730236949275e-09
                                    children [
                                      Shape {
                                        appearance DEF Wheel PBRAppearance {
                                          baseColor 0.93 0.423 0
                                          metalness 0.4
                                          emissiveColor 0.53 0.023 0
                                        }
                                        geometry DEF wheel Cylinder {
                                          height 0.03
                                          radius 0.05
                                        }
                                      }
                                    ]
                                    name "left_touch_sensor"
                                    boundingObject Cylinder {
                                      height 0.032
                                      radius 0.052
                                    }
                                    physics Physics {
                                      density -1
                                      mass 0.1
                                    }
                                    type "force-3d"
                                    lookupTable []
                                    linearVelocity -0.06040296082251693 -3.5232021138421567e-07 0.011763459081381303
                                    angularVelocity 0.22622020556155312 0.00024620255266056694 1.1615948636956068
                                  }
                                ]
                                boundingObject USE wheel
                                physics Physics {
                                  density -1
                                  mass 1
                                }
                                linearVelocity -0.06040288598922512 -2.257809503514542e-07 0.011763444377691466
                                angularVelocity 0.22622020974356796 0.00024620725805121166 1.1615948629351702
                              }
                            }
                          ]
                        }
                      ]
                      boundingObject USE Hip_link
                      physics Physics {
                        density -1
                        mass 0.1
                        centerOfMass [
                          0 -0.22 0
                        ]
                      }
                      linearVelocity -0.06054058096285399 -0.00020914288892031694 0.011818750650563835
                      angularVelocity 0.00047119902306505144 0.00029926143985764997 0.0023035773165480523
                    }
                  }
                ]
              }
            ]
            boundingObject USE Hip_link
            physics Physics {
              density -1
              mass 0.1
              centerOfMass [
                0 0 0
              ]
            }
            linearVelocity -0.06097165730909777 1.6662498627035e-05 0.011877592009716404
            angularVelocity 0.00047119917353910176 0.0002992661407573301 0.0023035772965136598
          }
        }
      ]
    }
    DEF RIGHT_LEG Transform {
      translation 0 0 0.125
      children [
        HingeJoint {
          jointParameters HingeJointParameters {
            position -0.9804916749623374
            axis 0 0 1
          }
          device [
            PositionSensor {
              name "right_hip_encoder"
            }
            RotationalMotor {
              name "right_hip_motor"
              maxVelocity 23.5
              maxTorque 35
            }
          ]
          endPoint DEF hip_link Solid {
            rotation 0 0 -1 0.9804916749623376
            children [
              USE Hip_link
              USE Hip_Motor_Transform
              Transform {
                translation 0 -0.22 0
                children [
                  HingeJoint {
                    jointParameters HingeJointParameters {
                      position 1.9328672651026475
                      axis 0 0 1
                    }
                    device [
                      PositionSensor {
                        name "right_keen_encoder"
                      }
                      RotationalMotor {
                        name "right_keen_motor"
                        maxVelocity 23.5
                        maxTorque 35
                      }
                    ]
                    endPoint Solid {
                      rotation 0 0 1 1.9328672651026475
                      children [
                        Solid {
                          children [
                            USE Hip_Motor_Transform
                          ]
                          name "solid(1)"
                          boundingObject USE Hip_Motor_Transform
                          physics Physics {
                            density -1
                            mass 0.1
                          }
                        }
                        USE Hip_link
                        Transform {
                          translation 0 -0.22 0
                          rotation 1 0 0 -0.000795307179585869
                          children [
                            USE Hip_Motor_Transform
                          ]
                        }
                        Transform {
                          translation 0 -0.11 0
                          children [
                            HingeJoint {
                              jointParameters HingeJointParameters {
                                position -17.889850336867024
                                axis 0 0 1
                                anchor 0 -0.11 0
                              }
                              device [
                                Brake {
                                  name "right_brake"
                                }
                                PositionSensor {
                                  name "right_wheel_encoder"
                                }
                                RotationalMotor {
                                  name "right_wheel_motor"
                                  maxVelocity 23.5
                                  maxTorque 35
                                }
                              ]
                              endPoint Solid {
                                translation -1.175321401353108e-05 -0.10999238764093419 0.024999993714566265
                                rotation 0.8054085604906283 0.4189491739059525 0.41928348449698577 1.784753313134511
                                children [
                                  TouchSensor {
                                    translation -6.112989027196036e-07 5.139817460531049e-10 -6.446444681396102e-07
                                    rotation 0.42659749091537835 0.0037492830922841876 0.9044338138421173 -3.5751575322218463e-09
                                    children [
                                      Shape {
                                        appearance USE Wheel
                                        geometry DEF wheel Cylinder {
                                          height 0.03
                                          radius 0.05
                                        }
                                      }
                                    ]
                                    name "right_touch_sensor"
                                    boundingObject Cylinder {
                                      height 0.032
                                      radius 0.052
                                    }
                                    physics Physics {
                                      density -1
                                      mass 0.1
                                    }
                                    type "force-3d"
                                    lookupTable []
                                    linearVelocity -0.060329643854466306 3.257439476577722e-07 0.011749177916826824
                                    angularVelocity 0.22594567866446344 0.00024636909891885816 1.1601849064602754
                                  }
                                ]
                                boundingObject USE wheel
                                physics Physics {
                                  density -1
                                  mass 1
                                }
                                linearVelocity -0.060329222109705316 5.927044446951598e-07 0.011749095831371755
                                angularVelocity 0.2259456745772386 0.0002463644808477056 1.1601849073040333
                              }
                            }
                          ]
                        }
                      ]
                      boundingObject USE Hip_link
                      physics Physics {
                        density -1
                        mass 0.1
                        centerOfMass [
                          0 -0.22 0
                        ]
                      }
                      linearVelocity -0.060467116641211856 -0.00021469542393687656 0.011804444256286453
                      angularVelocity 0.00047119949834001335 0.00029928018333854754 0.002303577077633066
                    }
                  }
                ]
              }
              Shape {
              }
            ]
            name "solid(1)"
            boundingObject USE Hip_link
            physics Physics {
              density -1
              mass 0.1
              centerOfMass [
                0 0 0
              ]
            }
            linearVelocity -0.06089819309049624 1.1110495481320481e-05 0.011863285843814304
            angularVelocity 0.0004711994907372987 0.00029927549404350494 0.0023035775182810923
          }
        }
      ]
    }
    DEF BODY Shape {
      appearance PBRAppearance {
        roughness 0.5
        metalness 0.5
      }
      geometry Box {
        size 0.15 0.1 0.23
      }
    }
  ]
  name "MiniNezha"
  contactMaterial "body"
  boundingObject USE BODY
  physics Physics {
    density -1
    mass 5
    centerOfMass [
      0 0 0
    ]
  }
  controller "my_controller_python"
  supervisor TRUE
  linearVelocity -0.0609349246511857 1.3886496534556193e-05 0.011870438820758085
  angularVelocity 0.00047119936097515916 0.0002992708252397984 0.0023035774002823943
}
Robot {
  translation 5.245711085500819e-12 0.019803799999999993 2.7996831484776132e-11
  rotation -4.622138780669455e-10 1 1.1546530285430417e-09 1.823565860645758e-10
  children [
    DEF ground_touch Shape {
      appearance PBRAppearance {
      }
      geometry Box {
        size 5 0.04 2
      }
    }
    TouchSensor {
      translation 6.82821278232472e-21 0.0199996076 -2.3662687263035634e-20
      rotation -6.355461150727158e-08 0.9999999999999978 2.620291728220358e-08 5.470697581986661e-10
      name "ground_touch_sensor"
      boundingObject Box {
        size 5 0.005 2
      }
      physics Physics {
        density -1
        mass 1
      }
      type "force-3d"
      lookupTable []
      linearVelocity 1.3844327348164224e-19 1.421055106377379e-17 -1.3810518467624045e-18
      angularVelocity 1.7987081342914292e-17 4.506263936455494e-21 3.836984933644266e-18
    }
  ]
  boundingObject USE ground_touch
  physics Physics {
    density -1
    mass 1
  }
  controller "ground"
  linearVelocity 2.564303082333396e-19 1.847411202677081e-16 -3.4035695670958586e-19
  angularVelocity -6.527395663884241e-27 4.504920617163471e-21 6.820773733778002e-18
}
