#VRML_SIM R2021a utf8
WorldInfo {
  CFM 1e-06
  ERP 0.6
  basicTimeStep 8
  coordinateSystem "NUE"
  contactProperties [
    ContactProperties {
      bounce 0
    }
    ContactProperties {
      material1 "body"
      coulombFriction [
        0
      ]
      bounce 0
    }
  ]
}
Viewpoint {
  orientation 0.743963882240224 0.666825578499601 0.04314382668153467 5.876796507324662
  position 0.2208144076662102 0.7514727154065457 0.11119027953367344
  follow "MiniNezha"
  followSmoothness 0
}
TexturedBackground {
}
TexturedBackgroundLight {
}
Floor {
}
Robot {
  translation 0.7170638075753082 0.25109975383726457 -2.071759212733614
  rotation -0.011566921657571139 0.9997602268176294 -0.01859288027524351 1.1091262567360771
  children [
    GPS {
    }
    Gyro {
    }
    InertialUnit {
      name "inertial_unit"
    }
    DEF LEFT_LEG Transform {
      translation 0 0 -0.125
      children [
        HingeJoint {
          jointParameters HingeJointParameters {
            position -1.1178607156545577
            axis 0 0 1
          }
          device [
            PositionSensor {
              name "left_hip_encoder"
            }
            RotationalMotor {
              name "left_hip_motor"
              maxVelocity 23.5
              maxTorque 35
            }
          ]
          endPoint Solid {
            rotation 0 0 -1 1.1178607156545575
            children [
              DEF Hip_Motor_Transform Transform {
                rotation 1 0 0 1.57
                children [
                  DEF Motor_Shape Shape {
                    appearance DEF Motor_Color PBRAppearance {
                      baseColor 0.9 0.9 0.9
                      metalness 0.2
                    }
                    geometry Cylinder {
                      height 0.03
                      radius 0.02
                    }
                  }
                ]
              }
              DEF Hip_link Transform {
                translation 0 -0.11 0
                children [
                  Shape {
                    appearance PBRAppearance {
                      baseColor 0 0.247 0.263
                      roughness 0.5
                      metalness 0.5
                      emissiveColor 0 0.047 0.063
                    }
                    geometry Box {
                      size 0.02 0.22 0.02
                    }
                  }
                ]
              }
              Transform {
                translation 0 -0.22 0
                children [
                  HingeJoint {
                    jointParameters HingeJointParameters {
                      position 2.1976848747215745
                      axis 0 0 1
                    }
                    device [
                      PositionSensor {
                        name "left_keen_encoder"
                      }
                      RotationalMotor {
                        name "left_keen_motor"
                        maxVelocity 0.1
                        maxTorque 35
                      }
                    ]
                    endPoint Solid {
                      rotation 0 0 1 2.1976848747215745
                      children [
                        Solid {
                          rotation 1 0 0 0
                          children [
                            USE Hip_Motor_Transform
                          ]
                          name "solid(1)"
                          boundingObject USE Hip_Motor_Transform
                          physics Physics {
                            density -1
                            mass 0.1
                          }
                        }
                        Transform {
                          translation 0 -0.22 0
                          rotation 1 0 0 -0.000795307179585869
                          children [
                            USE Hip_Motor_Transform
                          ]
                        }
                        USE Hip_link
                        Transform {
                          translation 0 -0.11 0
                          children [
                            HingeJoint {
                              jointParameters HingeJointParameters {
                                position -64.73010004995514
                                axis 0 0 1
                                anchor 0 -0.11 0
                              }
                              device [
                                Brake {
                                  name "left_brake"
                                }
                                DEF left_wheel_encoder PositionSensor {
                                  name "left_wheel_encoder"
                                }
                                RotationalMotor {
                                  name "left_wheel_motor"
                                  maxVelocity 23.5
                                  maxTorque 35
                                }
                              ]
                              endPoint Solid {
                                translation 0 -0.11 -0.025000000000000196
                                rotation 0.4517726617929399 -0.6305821375773241 -0.6310844870735889 2.292340749724264
                                children [
                                  TouchSensor {
                                    translation 4.6157738364804857e-07 -2.7935668223122434e-09 -6.344855305595587e-07
                                    rotation -0.8912880561393797 0.01299822505839031 -0.45325119649992873 1.1664622157070426e-08
                                    children [
                                      Shape {
                                        appearance DEF Wheel PBRAppearance {
                                          baseColor 0.93 0.423 0
                                          metalness 0.4
                                          emissiveColor 0.53 0.023 0
                                        }
                                        geometry DEF wheel Cylinder {
                                          height 0.03
                                          radius 0.05
                                        }
                                      }
                                    ]
                                    name "left_touch_sensor"
                                    boundingObject Cylinder {
                                      height 0.032
                                      radius 0.052
                                    }
                                    physics Physics {
                                      density -1
                                      mass 0.1
                                    }
                                    type "force-3d"
                                    lookupTable []
                                  }
                                ]
                                boundingObject USE wheel
                                physics Physics {
                                  density -1
                                  mass 1
                                }
                              }
                            }
                          ]
                        }
                      ]
                      boundingObject USE Hip_link
                      physics Physics {
                        density -1
                        mass 0.1
                        centerOfMass [
                          0 -0.22 0
                        ]
                      }
                    }
                  }
                ]
              }
            ]
            boundingObject USE Hip_link
            physics Physics {
              density -1
              mass 0.1
              centerOfMass [
                0 0 0
              ]
            }
          }
        }
      ]
    }
    DEF RIGHT_LEG Transform {
      translation 0 0 0.125
      children [
        HingeJoint {
          jointParameters HingeJointParameters {
            position -1.1178607154997169
            axis 0 0 1
          }
          device [
            PositionSensor {
              name "right_hip_encoder"
            }
            RotationalMotor {
              name "right_hip_motor"
              maxVelocity 5
              maxTorque 35
            }
          ]
          endPoint DEF hip_link Solid {
            rotation 0 0 -1 1.117860715499717
            children [
              USE Hip_link
              USE Hip_Motor_Transform
              Transform {
                translation 0 -0.22 0
                children [
                  HingeJoint {
                    jointParameters HingeJointParameters {
                      position 2.1976848743100588
                      axis 0 0 1
                    }
                    device [
                      PositionSensor {
                        name "right_keen_encoder"
                      }
                      RotationalMotor {
                        name "right_keen_motor"
                        maxVelocity 0.1
                        maxTorque 35
                      }
                    ]
                    endPoint Solid {
                      rotation 0 0 1 2.1976848743100588
                      children [
                        Solid {
                          children [
                            USE Hip_Motor_Transform
                          ]
                          name "solid(1)"
                          boundingObject USE Hip_Motor_Transform
                          physics Physics {
                            density -1
                            mass 0.1
                          }
                        }
                        USE Hip_link
                        Transform {
                          translation 0 -0.22 0
                          rotation 1 0 0 -0.000795307179585869
                          children [
                            USE Hip_Motor_Transform
                          ]
                        }
                        Transform {
                          translation 0 -0.11 0
                          children [
                            HingeJoint {
                              jointParameters HingeJointParameters {
                                position 8.216207801125462
                                axis 0 0 1
                                anchor 0 -0.11 0
                              }
                              device [
                                Brake {
                                  name "right_brake"
                                }
                                PositionSensor {
                                  name "right_wheel_encoder"
                                }
                                RotationalMotor {
                                  name "right_wheel_motor"
                                  maxVelocity 23.5
                                  maxTorque 35
                                }
                              ]
                              endPoint Solid {
                                translation -1.2905457455677885e-05 -0.11000543463136325 0.02499999371456619
                                rotation 0.43873439274614107 0.6351646128511794 0.6356713358358123 2.314113837502549
                                children [
                                  TouchSensor {
                                    translation -8.18359100485111e-08 3.2746300115960025e-09 2.852681235676613e-08
                                    rotation 0.22107962279219054 -0.012707357496546062 0.9751729710423263 -1.2328405935198611e-08
                                    children [
                                      Shape {
                                        appearance USE Wheel
                                        geometry DEF wheel Cylinder {
                                          height 0.03
                                          radius 0.05
                                        }
                                      }
                                    ]
                                    name "right_touch_sensor"
                                    boundingObject Cylinder {
                                      height 0.032
                                      radius 0.052
                                    }
                                    physics Physics {
                                      density -1
                                      mass 0.1
                                    }
                                    type "force-3d"
                                    lookupTable []
                                  }
                                ]
                                boundingObject USE wheel
                                physics Physics {
                                  density -1
                                  mass 1
                                }
                              }
                            }
                          ]
                        }
                      ]
                      boundingObject USE Hip_link
                      physics Physics {
                        density -1
                        mass 0.1
                        centerOfMass [
                          0 -0.22 0
                        ]
                      }
                    }
                  }
                ]
              }
              Shape {
              }
            ]
            name "solid(1)"
            boundingObject USE Hip_link
            physics Physics {
              density -1
              mass 0.1
              centerOfMass [
                0 0 0
              ]
            }
          }
        }
      ]
    }
    DEF BODY Shape {
      appearance PBRAppearance {
        roughness 0.5
        metalness 0.5
      }
      geometry Box {
        size 0.15 0.1 0.23
      }
    }
  ]
  name "MiniNezha"
  contactMaterial "body"
  boundingObject USE BODY
  physics Physics {
    density -1
    mass 5
    centerOfMass [
      0 0 0
    ]
  }
  controller "my_controller_python"
  supervisor TRUE
}
Robot {
  translation 5.2457109212332404e-12 0.019803799999999993 2.799683154675238e-11
  rotation 7.01597270167658e-09 1 -2.4360825331959666e-09 1.8235658607600302e-10
  children [
    DEF ground_touch Shape {
      appearance PBRAppearance {
      }
      geometry Box {
        size 5 0.04 2
      }
    }
    TouchSensor {
      translation 9.851375359859907e-21 0.019999346000000005 -2.2970385557942766e-20
      rotation -3.650633707839255e-08 0.9999999999999992 1.4958549768207886e-08 9.117829303535634e-10
      name "ground_touch_sensor"
      boundingObject Box {
        size 5 0.005 2
      }
      physics Physics {
        density -1
        mass 1
      }
      type "force-3d"
      lookupTable []
    }
  ]
  boundingObject USE ground_touch
  physics Physics {
    density -1
    mass 1
  }
  controller "ground"
}
